Workbook
Name \0: #REF!
Name \0: #REF!
Name \a: #REF!
Name \a: #REF!
Name \m: #REF!
Name \q: #REF!
Name ____L84: Bib!____L84
Name ____L84: #N/A
Name ____L84: #N/A
Name ____L84: 'Dark current'!____L84
Name ____L84: #N/A
Name ____L84: 'Flex_Vs_XDD (3)'!____L84
Name ____L84: Bib!____L84
Name ___L84: Bib!___L84
Name ___L84: #N/A
Name ___L84: #N/A
Name ___L84: 'Dark current'!___L84
Name ___L84: #N/A
Name ___L84: 'Flex_Vs_XDD (3)'!___L84
Name ___L84: Bib!___L84
Name __L84: Bib!__L84
Name __L84: #N/A
Name __L84: #N/A
Name __L84: 'Dark current'!__L84
Name __L84: #N/A
Name __L84: 'Flex_Vs_XDD (3)'!__L84
Name __L84: Bib!__L84
Name _005明細事業部: #REF!
Name _012事業部明細: #REF!
Name _101事業部明細: #REF!
Name _19565: #REF!
Name _IND84: '[1]CHIFFRAGE CAISSE BK91'!$Q$3
Name _IND91: '[1]CHIFFRAGE CAISSE BK91'!$P$3
Name _L84: Bib!_L84
Name _L84: #N/A
Name _L84: #N/A
Name _L84: 'Dark current'!_L84
Name _L84: #N/A
Name _L84: 'Flex_Vs_XDD (3)'!_L84
Name _L84: Bib!_L84
Name _M13: [2]FEUTRE!#REF!
Name _M14: [2]FEUTRE!#REF!
Name _M16: [2]FEUTRE!#REF!
Name _M3: [2]FEUTRE!#REF!
Name _M4: [2]FEUTRE!#REF!
Name _M8: [2]FEUTRE!#REF!
Name _MS15: [2]FEUTRE!#REF!
Name _R7: [2]FEUTRE!#REF!
Name ○と×: #REF!
Name A1A: #REF!
Name aaa: #REF!
Name Abattant: #REF!
Name AccessButton: "PostK9b1_Synthèse_composants_Liste"
Name aci: #REF!
Name AcPilote_i: #REF!
Name afficherMasquerLesFeuilles: #N/A
Name afficherMasquerLesFeuilles: #N/A
Name afficherMasquerLesFeuilles: #N/A
Name afficherMasquerLesFeuilles: 'Model Change Wh '!afficherMasquerLesFeuilles
Name afficherMasquerLesFeuilles: 'Model Change Wh '!afficherMasquerLesFeuilles

Sheet Mounting Mode
A1: System | B1: Device (LCABLE) | C1: Name (LCABLE) | D1: Free Explanation | E1: Low Power needs | F1: Load Technical Wake up 8h | G1: Load Dark Current | H1: SmartMOS Dark Current | I1: Total Dark Current | J1: 0 | K1: =J1+12 -> 12 | L1: =K1+12 -> 24 | M1: =L1+12 -> 36 | N1: =M1+12 -> 48 | O1: =N1+12 -> 60 | P1: =O1+12 -> 72 | Q1: =P1+12 -> 84 | R1: =Q1+12 -> 96 | ... AL1: =AK1+12 -> 336
B2: 1094 | C2: VDC | E2: Fusible + Bat | G2: 330 | I2: =G2+H2 -> 330 | J2: 1 | K2: 1 | L2: 1 | M2: 1 | N2: 1 | O2: 1 | P2: 1 | Q2: 1 | R2: 1 | S2: 1 | T2: 1 | U2: 1 | V2: 1 | W2: 1 | X2: 1 | Y2: 1 | Z2: 1 | AA2: 1 | AB2: 1 | AC2: 1 | AD2: 1 | AE2: 1 | AF2: 1 | AG2: 1 | AH2: 1 | AI2: 1 | AJ2: 1 | AK2: 1 | AL2: 1
B3: 1232 | C3: EPS | E3: Fusible + Bat | G3: 71 | I3: =G3+H3 -> 71 | J3: 1 | K3: 1 | L3: 1 | M3: 1 | N3: 1 | O3: 1 | P3: 1 | Q3: 1 | R3: 1 | S3: 1 | T3: 1 | U3: 1 | V3: 1 | W3: 1 | X3: 1 | Y3: 1 | Z3: 1 | AA3: 1 | AB3: 1 | AC3: 1 | AD3: 1 | AE3: 1 | AF3: 1 | AG3: 1 | AH3: 1 | AI3: 1 | AJ3: 1 | AK3: 1 | AL3: 1
B4: 2848 | C4: AIBS | E4: Fusible + Bat | F4: 0.1 | G4: 106 | I4: =G4+H4 -> 106 | J4: 1 | K4: 1 | L4: 1 | M4: 1 | N4: 1 | O4: 1 | P4: 1 | Q4: 1 | R4: 1 | S4: 1 | T4: 1 | U4: 1 | V4: 1 | W4: 1 | X4: 1 | Y4: 1 | Z4: 1 | AA4: 1 | AB4: 1 | AC4: 1 | AD4: 1 | AE4: 1 | AF4: 1 | AG4: 1 | AH4: 1 | AI4: 1 | AJ4: 1 | AK4: 1 | AL4: 1
C5: PIU Master | F5: 0.35 | G5: 600 | I5: =G5+H5 -> 600 | J5: 1 | K5: 1 | L5: 1 | M5: 1 | N5: 1 | O5: 1 | P5: 1 | Q5: 1 | R5: 1 | S5: 1 | T5: 1 | U5: 1 | V5: 1 | W5: 1 | X5: 1 | Y5: 1 | Z5: 1 | AA5: 1 | AB5: 1 | AC5: 1 | AD5: 1 | AE5: 1 | AF5: 1 | AG5: 1 | AH5: 1 | AI5: 1 | AJ5: 1 | AK5: 1 | AL5: 1
C6: PIU Sub Cabin | F6: 0.3 | G6: 310 | I6: =G6+H6 -> 310 | J6: 1 | K6: 1 | L6: 1 | M6: 1 | N6: 1 | O6: 1 | P6: 1 | Q6: 1 | R6: 1 | S6: 1 | T6: 1 | U6: 1 | V6: 1 | W6: 1 | X6: 1 | Y6: 1 | Z6: 1 | AA6: 1 | AB6: 1 | AC6: 1 | AD6: 1 | AE6: 1 | AF6: 1 | AG6: 1 | AH6: 1 | AI6: 1 | AJ6: 1 | AK6: 1 | AL6: 1
C7: PIU Hood | F7: 0.3 | G7: 360 | I7: =G7+H7 -> 360 | J7: 1 | K7: 1 | L7: 1 | M7: 1 | N7: 1 | O7: 1 | P7: 1 | Q7: 1 | R7: 1 | S7: 1 | T7: 1 | U7: 1 | V7: 1 | W7: 1 | X7: 1 | Y7: 1 | Z7: 1 | AA7: 1 | AB7: 1 | AC7: 1 | AD7: 1 | AE7: 1 | AF7: 1 | AG7: 1 | AH7: 1 | AI7: 1 | AJ7: 1 | AK7: 1 | AL7: 1
C8: DSM Power Parking | G8: 100 | I8: =G8+H8 -> 100 | J8: 1 | K8: 1 | L8: 1 | M8: 1 | N8: 1 | O8: 1 | P8: 1 | Q8: 1 | R8: 1 | S8: 1 | T8: 1 | U8: 1 | V8: 1 | W8: 1 | X8: 1 | Y8: 1 | Z8: 1 | AA8: 1 | AB8: 1 | AC8: 1 | AD8: 1 | AE8: 1 | AF8: 1 | AG8: 1 | AH8: 1 | AI8: 1 | AJ8: 1 | AK8: 1 | AL8: 1
C9: DSM Power Adapation | G9: 100 | I9: =G9+H9 -> 100 | J9: 1 | K9: 1 | L9: 1 | M9: 1 | N9: 1 | O9: 1 | P9: 1 | Q9: 1 | R9: 1 | S9: 1 | T9: 1 | U9: 1 | V9: 1 | W9: 1 | X9: 1 | Y9: 1 | Z9: 1 | AA9: 1 | AB9: 1 | AC9: 1 | AD9: 1 | AE9: 1 | AF9: 1 | AG9: 1 | AH9: 1 | AI9: 1 | AJ9: 1 | AK9: 1 | AL9: 1
C10: DSM Winter | G10: 100 | I10: =G10+H10 -> 100 | J10: 1 | K10: 1 | L10: 1 | M10: 1 | N10: 1 | O10: 1 | P10: 1 | Q10: 1 | R10: 1 | S10: 1 | T10: 1 | U10: 1 | V10: 1 | W10: 1 | X10: 1 | Y10: 1 | Z10: 1 | AA10: 1 | AB10: 1 | AC10: 1 | AD10: 1 | AE10: 1 | AF10: 1 | AG10: 1 | AH10: 1 | AI10: 1 | AJ10: 1 | AK10: 1 | AL10: 1
C11: DSM H2 | G11: 100 | I11: =G11+H11 -> 100 | J11: 1 | K11: 1 | L11: 1 | M11: 1 | N11: 1 | O11: 1 | P11: 1 | Q11: 1 | R11: 1 | S11: 1 | T11: 1 | U11: 1 | V11: 1 | W11: 1 | X11: 1 | Y11: 1 | Z11: 1 | AA11: 1 | AB11: 1 | AC11: 1 | AD11: 1 | AE11: 1 | AF11: 1 | AG11: 1 | AH11: 1 | AI11: 1 | AJ11: 1 | AK11: 1 | AL11: 1
C12: DSM Trailer | G12: 100 | I12: =G12+H12 -> 100 | J12: 1 | K12: 1 | L12: 1 | M12: 1 | N12: 1 | O12: 1 | P12: 1 | Q12: 1 | R12: 1 | S12: 1 | T12: 1 | U12: 1 | V12: 1 | W12: 1 | X12: 1 | Y12: 1 | Z12: 1 | AA12: 1 | AB12: 1 | AC12: 1 | AD12: 1 | AE12: 1 | AF12: 1 | AG12: 1 | AH12: 1 | AI12: 1 | AJ12: 1 | AK12: 1 | AL12: 1
B13: 2637 | C13: DCDC | D13: DCDC | F13: 0.3 | G13: 200 | H13: 45 | I13: =G13+H13 -> 245 | J13: 1 | K13: 1 | L13: 1 | M13: 1 | N13: 1 | O13: 1 | P13: 1 | Q13: 1 | R13: 1 | S13: 1 | T13: 1 | U13: 1 | V13: 1 | W13: 1 | X13: 1 | Y13: 1 | Z13: 1 | AA13: 1 | AB13: 1 | AC13: 1 | AD13: 1 | AE13: 1 | AF13: 1 | AG13: 1 | AH13: 1 | AI13: 1 | AJ13: 1 | AK13: 1 | AL13: 1
A14: S20 Electrical Energy Storage for traction | B14: 2656 | C14: BMS MAIN MONITORING TRACTION BATTERY HIGH VOLTAGE | D14: BMS/BMS2 power supply | E14: Cust : if 12V Bat OK | F14: 0.054 | G14: 100 | H14: 45 | I14: =G14+H14 -> 145 | J14: 1 | K14: 1 | L14: 1 | M14: 1 | N14: 1 | O14: 1 | P14: 1 | Q14: 1 | R14: 1 | S14: 1 | T14: 1 | U14: 1 | V14: 1 | W14: 1 | X14: 1 | Y14: 1 | Z14: 1 | AA14: 1 | AB14: 1 | AC14: 1 | AD14: 1 | AE14: 1 | AF14: 1 | AG14: 1 | AH14: 1 | AI14: 1 | AJ14: 1 | AK14: 1 | AL14: 1
A15: S53 Power Distribution | B15: 2990 | C15: PCU PHYSICAL COMPUTING UNIT | D15: Main Microcontroller | G15: 760 | H15: 45 | I15: =G15+H15 -> 805 | J15: 1 | K15: 1 | L15: 1 | M15: 1 | N15: 1 | O15: 1 | P15: 1 | Q15: 1 | R15: 1 | S15: 1 | T15: 1 | U15: 1 | V15: 1 | W15: 1 | X15: 1 | Y15: 1 | Z15: 1
A16: S10 Braking and Electronic stability control | B16: 160 | C16: STOP LIGHT SWITCH (Normally closed for Stop Lamp) | D16: Brake pedal | E16: Cust : <12h | G16: 0 | H16: 45 | I16: =G16+H16 -> 45
A17: S22 Connectivity | B17: 2152 | C17: IVC TELEMATIC ECU | D17: IVC Smart Antenna + eCall Keyboard | E17: Cust : <7 days | G17: 360 | H17: 45 | I17: =G17+H17 -> 405 | J17: 1 | K17: 1 | L17: 1 | M17: 1 | N17: 1 | O17: 1 | P17: 1 | Q17: 1 | R17: 1 | S17: 1 | T17: 1 | U17: 1 | V17: 1 | W17: 1 | X17: 1 | Y17: 1 | Z17: 1 | AA17: 1 | AB17: 1 | AC17: 1 | AD17: 1 | AE17: 1 | AF17: 1 | AG17: 1 | AH17: 1 | AI17: 1 | AJ17: 1 | AK17: 1 | AL17: 1
A18: S22 Connectivity | B18: 2893 | C18: BLUETOOTH LOW ENERGY MODULE | D18: BLM/IDG | E18: Cust : if 12V Bat OK | G18: 100 | H18: 45 | I18: =G18+H18 -> 145
A19: S28 Access and Vehicle Protection | B19: 2003 | C19: HANDS-FREE ACCESS ECU | D19: KAM | E19: Cust : if 12V Bat OK | G19: 720 | H19: 45 | I19: =G19+H19 -> 765
A20: S21 Multimedia | B20: XXX | C20: COCKPIT DOMAIN CONTROLLER - Power 1 | D20: CDC | E20: Cust < 72h | G20: 100 | H20: 45 | I20: =G20+H20 -> 145
A21: S29 Display and Command and Sound | B21: 849 | C21: MULTIFONCTIONNAL ELECTRIC CONTROL | D21: Capacitive Hazard & Doorlock button --> Wake up | E21: Cust : <12h | G21: 100 | H21: 45 | I21: =G21+H21 -> 145
A22: S48 External lighting and signalling | B22: 1519 | C22: UNDER STEERING WHEEL CONTROLS | D22: CombiSwitch ECU (CSV) to let customer to select wiping speed & light commands | G22: 22 | H22: 45 | I22: =G22+H22 -> 67 | J22: 1 | K22: 1 | L22: 1 | M22: 1 | N22: 1 | O22: 1 | P22: 1 | Q22: 1 | R22: 1 | S22: 1 | T22: 1 | U22: 1 | V22: 1 | W22: 1 | X22: 1 | Y22: 1 | Z22: 1 | AA22: 1 | AB22: 1 | AC22: 1 | AD22: 1 | AE22: 1 | AF22: 1 | AG22: 1 | AH22: 1 | AI22: 1 | AJ22: 1 | AK22: 1 | AL22: 1
A23: S48 External lighting and signalling | B23: XXXX | C23: DASHBOARD EXTERNAL LIGHT CONTROL BUTTONS | D23: Mercedes Like | E23: Cust : <12h | G23: 100 | H23: 45 | I23: =G23+H23 -> 145
A24: S53 Power Distribution | B24: 225 | C24: DIAGNOSTIC SOCKET | D24: OBD Plug | E24: Factory DM0 | G24: 100 | H24: 45 | I24: =G24+H24 -> 145 | J24: 1 | K24: 1 | L24: 1 | M24: 1 | N24: 1 | O24: 1 | P24: 1 | Q24: 1 | R24: 1 | S24: 1 | T24: 1 | U24: 1 | V24: 1 | W24: 1 | X24: 1 | Y24: 1 | Z24: 1 | AA24: 1 | AB24: 1 | AC24: 1 | AD24: 1 | AE24: 1 | AF24: 1 | AG24: 1 | AH24: 1 | AI24: 1 | AJ24: 1 | AK24: 1 | AL24: 1
A25: S43 Seats and Driving posture | B25: 2567 | C25: LEFT HAND FRONT SEAT MEMORY ECU | D25: Driver Electrical Seat | E25: Cust : <12h | G25: 117 | H25: 45 | I25: =G25+H25 -> 162
A26: S43 Seats and Driving posture | B26: 2576 | C26: RIGHT HAND FRONT SEAT MEMORY ECU | D26: Passenger Electrical Seat | E26: Cust : <12h | G26: 117 | H26: 45 | I26: =G26+H26 -> 162
A27: S45 Laterals doors | B27: 3016 | C27: RIGHT SLIDING DOOR | D27: Power Sliding Door (Right Side) | E27: Cust <1h | G27: 220 | H27: 45 | I27: =G27+H27 -> 265
A28: S45 Laterals doors | B28: 3017 | C28: LEFT SLIDING DOOR | D28: Power Sliding Door (Left Side) | E28: Cust <1h | G28: 220 | H28: 45 | I28: =G28+H28 -> 265
A29: S46 Back door and Tailgate | B29: 1048 | C29: ECDO TAILGATE ECU | D29: Power BackDoor | E29: Cust <1h | G29: 100 | H29: 45 | I29: =G29+H29 -> 145
B31: 946 | C31: HEVC / PDC | D31: HEVC / PDC | F31: 0.3 | G31: 115 | H31: 45 | I31: =G31+H31 -> 160 | J31: 1 | K31: 1 | L31: 1 | M31: 1 | N31: 1 | O31: 1 | P31: 1 | Q31: 1 | R31: 1 | S31: 1 | T31: 1 | U31: 1 | V31: 1 | W31: 1 | X31: 1 | Y31: 1 | Z31: 1 | AA31: 1 | AB31: 1 | AC31: 1 | AD31: 1 | AE31: 1 | AF31: 1 | AG31: 1 | AH31: 1 | AI31: 1 | AJ31: 1 | AK31: 1 | AL31: 1
A33: S30 Engine Start and Stop | B33: 2918 | C33: ALCOHOL INTERLOCK DEVICE ECU | D33: Ethylotest | E33: Cust : if 12V Bat OK | G33: 1000 | H33: 45 | I33: =G33+H33 -> 1045
A34: S28 Access and Vehicle Protection | B34: 2671, 1838,2496,2497 | C34: VOLUMETRIC ALARM ECU | D34: Volumic Alarm | E34: Cust : if 12V Bat OK | G34: 8100 | H34: 45 | I34: =G34+H34 -> 8145
B35: XXX | C35: CHRONOTACHYGRAPHE | D35: 2.5t or 9 peoples | E35: Cust : if 12V Bat OK | G35: 14000 | H35: 45 | I35: =G35+H35 -> 14045
A37: S27 batterie LIB 12V | C37: BMS LIB 12V | D37: BMS LIB 12V | F37: 0.001 | G37: 1500 | H37: 45 | I37: =G37+H37 -> 1545 | J37: 1 | K37: 1 | L37: 1 | M37: 1 | N37: 1 | O37: 1 | P37: 1 | Q37: 1 | R37: 1 | S37: 1 | T37: 1 | U37: 1 | V37: 1 | W37: 1 | X37: 1 | Y37: 1 | Z37: 1 | AA37: 1 | AB37: 1 | AC37: 1 | AD37: 1 | AE37: 1 | AF37: 1 | AG37: 1 | AH37: 1 | AI37: 1 | AJ37: 1 | AK37: 1 | AL37: 1
C39: VAN / DELIVERY / CARGO | D39: Dark Current µA | F39: =SUM(F3:F36) -> 1.704 | G39: =SUMPRODUCT($J2:$J36,G2:G36) -> 3934 | H39: =SUMPRODUCT($J2:$J36,H2:H36) -> 315 | I39: =SUM(I2:I36) -> 29873 | K39: =SUMPRODUCT($I2:$I36,K2:K36) -> 4249 | L39: =SUMPRODUCT($I2:$I36,L2:L36) -> 4249 | M39: =SUMPRODUCT($I2:$I36,M2:M36) -> 4249 | N39: =SUMPRODUCT($I2:$I36,N2:N36) -> 4249 | O39: =SUMPRODUCT($I2:$I36,O2:O36) -> 4249 | P39: =SUMPRODUCT($I2:$I36,P2:P36) -> 4249 | Q39: =SUMPRODUCT($I2:$I36,Q2:Q36) -> 4249 | R39: =SUMPRODUCT($I2:$I36,R2:R36) -> 4249 | ... AL39: =SUMPRODUCT($I2:$I36,AL2:AL36) -> 3444
D40: Dark Current mA | F40: =F39*1000 -> 1704 | G40: =G39/1000 -> 3.934 | H40: =H39/1000 -> 0.315 | I40: =I39/1000 -> 29.873 | K40: =K39/1000 -> 4.249 | L40: =L39/1000 -> 4.249 | M40: =M39/1000 -> 4.249 | N40: =N39/1000 -> 4.249 | O40: =O39/1000 -> 4.249 | P40: =P39/1000 -> 4.249 | Q40: =Q39/1000 -> 4.249 | R40: =R39/1000 -> 4.249 | ... AL40: =AL39/1000 -> 3.444
D41: 12h Energy mAh | F41: =(F39-F14-F31-F13) -> 1.05 | K41: =K40*12 -> 50.988 | L41: =L40*12 -> 50.988 | M41: =M40*12 -> 50.988 | N41: =N40*12 -> 50.988 | O41: =O40*12 -> 50.988 | P41: =P40*12 -> 50.988 | Q41: =Q40*12 -> 50.988 | R41: =R40*12 -> 50.988 | ... AL41: =AL40*12 -> 41.328
D42: LP Energy mAh | F42: =F41*1000 -> 1050 | K42: =K41+J41 -> 50.988 | L42: =L41+K42 -> 101.976 | M42: =M41+L42 -> 152.964 | N42: =N41+M42 -> 203.952 | O42: =O41+N42 -> 254.94 | P42: =P41+O42 -> 305.928 | Q42: =Q41+P42 -> 356.916 | R42: =R41+Q42 -> 407.904 | S42: =S41+R42 -> 458.892 | ... AL42: =AL41+AK42 -> 1311.744
K43: 12 heures | P43: 3 jours | R43: 4 jours | Z43: 8 Jours | AH43: 12 Jours
C45: PEOPLE MOVER | D45: Dark Current µA | F45: =SUM(F2:F37) -> 1.705 | G45: =SUMPRODUCT($J2:$J37,G2:G37) -> 5434 | H45: =SUMPRODUCT($J2:$J37,H2:H37) -> 360 | I45: =SUM(I2:I37) -> 31418 | K45: =SUMPRODUCT($I2:$I37,K2:K37) -> 5794 | L45: =SUMPRODUCT($I2:$I37,L2:L37) -> 5794 | M45: =SUMPRODUCT($I2:$I37,M2:M37) -> 5794 | N45: =SUMPRODUCT($I2:$I37,N2:N37) -> 5794 | O45: =SUMPRODUCT($I2:$I37,O2:O37) -> 5794 | P45: =SUMPRODUCT($I2:$I37,P2:P37) -> 5794 | Q45: =SUMPRODUCT($I2:$I37,Q2:Q37) -> 5794 | R45: =SUMPRODUCT($I2:$I37,R2:R37) -> 5794 | ... AL45: =SUMPRODUCT($I2:$I37,AL2:AL37) -> 4989
...

Sheet Logistic Mode
A1: System | B1: Device (LCABLE) | C1: Name (LCABLE) | D1: Free Explanation | E1: Low Power needs | F1: Load Technical Wake up 8h | G1: Load Dark Current | H1: SmartMOS Dark Current | I1: Total Dark Current | J1: 0 | K1: =J1+12 -> 12 | L1: =K1+12 -> 24 | M1: =L1+12 -> 36 | N1: =M1+12 -> 48 | O1: =N1+12 -> 60 | P1: =O1+12 -> 72 | Q1: =P1+12 -> 84 | R1: =Q1+12 -> 96 | ... GH1: =GG1+12 -> 2160
B2: 1094 | C2: VDC | E2: Fusible + Bat | G2: 53 | I2: =G2+H2 -> 53 | J2: 1 | K2: 1 | L2: 1 | M2: 1 | N2: 1 | O2: 1 | P2: 1 | Q2: 1 | R2: 1 | S2: 1 | T2: 1 | U2: 1 | V2: 1 | W2: 1 | X2: 1 | Y2: 1 | Z2: 1 | AA2: 1 | AB2: 1 | AC2: 1 | AD2: 1 | AE2: 1 | AF2: 1 | AG2: 1 | AH2: 1 | AI2: 1 | AJ2: 1 | AK2: 1 | AL2: 1 | AM2: 1 | AN2: 1 | AO2: 1 | AP2: 1 | AQ2: 1 | AR2: 1 | AS2: 1 | AT2: 1 | AU2: 1 | AV2: 1 | AW2: 1 | AX2: 1 | AY2: 1 | AZ2: 1 | BA2: 1 | BB2: 1 | BC2: 1 | BD2: 1 | BE2: 1 | BF2: 1 | BG2: 1 | BH2: 1 | BI2: 1 | BJ2: 1 | BK2: 1 | BL2: 1 | BM2: 1 | BN2: 1 | BO2: 1 | BP2: 1 | BQ2: 1 | BR2: 1 | BS2: 1 | BT2: 1 | BU2: 1 | BV2: 1 | BW2: 1 | BX2: 1 | BY2: 1 | BZ2: 1 | CA2: 1 | CB2: 1 | CC2: 1 | CD2: 1 | CE2: 1 | CF2: 1 | CG2: 1 | CH2: 1 | CI2: 1 | CJ2: 1 | CK2: 1 | CL2: 1 | CM2: 1 | CN2: 1 | CO2: 1 | CP2: 1 | CQ2: 1 | CR2: 1 | CS2: 1 | CT2: 1 | CU2: 1 | CV2: 1 | CW2: 1 | CX2: 1 | CY2: 1 | CZ2: 1 | DA2: 1 | DB2: 1 | DC2: 1 | DD2: 1 | DE2: 1 | DF2: 1 | DG2: 1 | DH2: 1 | DI2: 1 | DJ2: 1 | DK2: 1 | DL2: 1 | DM2: 1 | DN2: 1 | DO2: 1 | DP2: 1 | DQ2: 1 | DR2: 1 | DS2: 1 | DT2: 1 | DU2: 1 | DV2: 1 | DW2: 1 | DX2: 1 | DY2: 1 | DZ2: 1 | EA2: 1 | EB2: 1 | EC2: 1 | ED2: 1 | EE2: 1 | EF2: 1 | EG2: 1 | EH2: 1 | EI2: 1 | EJ2: 1 | EK2: 1 | EL2: 1 | EM2: 1 | EN2: 1 | EO2: 1 | EP2: 1 | EQ2: 1 | ER2: 1 | ES2: 1 | ET2: 1 | EU2: 1 | EV2: 1 | EW2: 1 | EX2: 1 | EY2: 1 | EZ2: 1 | FA2: 1 | FB2: 1 | FC2: 1 | FD2: 1 | FE2: 1 | FF2: 1 | FG2: 1 | FH2: 1 | FI2: 1 | FJ2: 1 | FK2: 1 | FL2: 1 | FM2: 1 | FN2: 1 | FO2: 1 | FP2: 1 | FQ2: 1 | FR2: 1 | FS2: 1 | FT2: 1 | FU2: 1 | FV2: 1 | FW2: 1 | FX2: 1 | FY2: 1 | FZ2: 1 | GA2: 1 | GB2: 1 | GC2: 1 | GD2: 1 | GE2: 1 | GF2: 1 | GG2: 1 | GH2: 1
B3: 1232 | C3: EPS | E3: Fusible + Bat | G3: 60 | I3: =G3+H3 -> 60 | J3: 1 | K3: 1 | L3: 1 | M3: 1 | N3: 1 | O3: 1 | P3: 1 | Q3: 1 | R3: 1 | S3: 1 | T3: 1 | U3: 1 | V3: 1 | W3: 1 | X3: 1 | Y3: 1 | Z3: 1 | AA3: 1 | AB3: 1 | AC3: 1 | AD3: 1 | AE3: 1 | AF3: 1 | AG3: 1 | AH3: 1 | AI3: 1 | AJ3: 1 | AK3: 1 | AL3: 1 | AM3: 1 | AN3: 1 | AO3: 1 | AP3: 1 | AQ3: 1 | AR3: 1 | AS3: 1 | AT3: 1 | AU3: 1 | AV3: 1 | AW3: 1 | AX3: 1 | AY3: 1 | AZ3: 1 | BA3: 1 | BB3: 1 | BC3: 1 | BD3: 1 | BE3: 1 | BF3: 1 | BG3: 1 | BH3: 1 | BI3: 1 | BJ3: 1 | BK3: 1 | BL3: 1 | BM3: 1 | BN3: 1 | BO3: 1 | BP3: 1 | BQ3: 1 | BR3: 1 | BS3: 1 | BT3: 1 | BU3: 1 | BV3: 1 | BW3: 1 | BX3: 1 | BY3: 1 | BZ3: 1 | CA3: 1 | CB3: 1 | CC3: 1 | CD3: 1 | CE3: 1 | CF3: 1 | CG3: 1 | CH3: 1 | CI3: 1 | CJ3: 1 | CK3: 1 | CL3: 1 | CM3: 1 | CN3: 1 | CO3: 1 | CP3: 1 | CQ3: 1 | CR3: 1 | CS3: 1 | CT3: 1 | CU3: 1 | CV3: 1 | CW3: 1 | CX3: 1 | CY3: 1 | CZ3: 1 | DA3: 1 | DB3: 1 | DC3: 1 | DD3: 1 | DE3: 1 | DF3: 1 | DG3: 1 | DH3: 1 | DI3: 1 | DJ3: 1 | DK3: 1 | DL3: 1 | DM3: 1 | DN3: 1 | DO3: 1 | DP3: 1 | DQ3: 1 | DR3: 1 | DS3: 1 | DT3: 1 | DU3: 1 | DV3: 1 | DW3: 1 | DX3: 1 | DY3: 1 | DZ3: 1 | EA3: 1 | EB3: 1 | EC3: 1 | ED3: 1 | EE3: 1 | EF3: 1 | EG3: 1 | EH3: 1 | EI3: 1 | EJ3: 1 | EK3: 1 | EL3: 1 | EM3: 1 | EN3: 1 | EO3: 1 | EP3: 1 | EQ3: 1 | ER3: 1 | ES3: 1 | ET3: 1 | EU3: 1 | EV3: 1 | EW3: 1 | EX3: 1 | EY3: 1 | EZ3: 1 | FA3: 1 | FB3: 1 | FC3: 1 | FD3: 1 | FE3: 1 | FF3: 1 | FG3: 1 | FH3: 1 | FI3: 1 | FJ3: 1 | FK3: 1 | FL3: 1 | FM3: 1 | FN3: 1 | FO3: 1 | FP3: 1 | FQ3: 1 | FR3: 1 | FS3: 1 | FT3: 1 | FU3: 1 | FV3: 1 | FW3: 1 | FX3: 1 | FY3: 1 | FZ3: 1 | GA3: 1 | GB3: 1 | GC3: 1 | GD3: 1 | GE3: 1 | GF3: 1 | GG3: 1 | GH3: 1
B4: 2848 | C4: AIBS | E4: Fusible + Bat | F4: 0 | G4: 61 | I4: =G4+H4 -> 61 | J4: 1 | K4: 1 | L4: 1 | M4: 1 | N4: 1 | O4: 1 | P4: 1 | Q4: 1 | R4: 1 | S4: 1 | T4: 1 | U4: 1 | V4: 1 | W4: 1 | X4: 1 | Y4: 1 | Z4: 1 | AA4: 1 | AB4: 1 | AC4: 1 | AD4: 1 | AE4: 1 | AF4: 1 | AG4: 1 | AH4: 1 | AI4: 1 | AJ4: 1 | AK4: 1 | AL4: 1 | AM4: 1 | AN4: 1 | AO4: 1 | AP4: 1 | AQ4: 1 | AR4: 1 | AS4: 1 | AT4: 1 | AU4: 1 | AV4: 1 | AW4: 1 | AX4: 1 | AY4: 1 | AZ4: 1 | BA4: 1 | BB4: 1 | BC4: 1 | BD4: 1 | BE4: 1 | BF4: 1 | BG4: 1 | BH4: 1 | BI4: 1 | BJ4: 1 | BK4: 1 | BL4: 1 | BM4: 1 | BN4: 1 | BO4: 1 | BP4: 1 | BQ4: 1 | BR4: 1 | BS4: 1 | BT4: 1 | BU4: 1 | BV4: 1 | BW4: 1 | BX4: 1 | BY4: 1 | BZ4: 1 | CA4: 1 | CB4: 1 | CC4: 1 | CD4: 1 | CE4: 1 | CF4: 1 | CG4: 1 | CH4: 1 | CI4: 1 | CJ4: 1 | CK4: 1 | CL4: 1 | CM4: 1 | CN4: 1 | CO4: 1 | CP4: 1 | CQ4: 1 | CR4: 1 | CS4: 1 | CT4: 1 | CU4: 1 | CV4: 1 | CW4: 1 | CX4: 1 | CY4: 1 | CZ4: 1 | DA4: 1 | DB4: 1 | DC4: 1 | DD4: 1 | DE4: 1 | DF4: 1 | DG4: 1 | DH4: 1 | DI4: 1 | DJ4: 1 | DK4: 1 | DL4: 1 | DM4: 1 | DN4: 1 | DO4: 1 | DP4: 1 | DQ4: 1 | DR4: 1 | DS4: 1 | DT4: 1 | DU4: 1 | DV4: 1 | DW4: 1 | DX4: 1 | DY4: 1 | DZ4: 1 | EA4: 1 | EB4: 1 | EC4: 1 | ED4: 1 | EE4: 1 | EF4: 1 | EG4: 1 | EH4: 1 | EI4: 1 | EJ4: 1 | EK4: 1 | EL4: 1 | EM4: 1 | EN4: 1 | EO4: 1 | EP4: 1 | EQ4: 1 | ER4: 1 | ES4: 1 | ET4: 1 | EU4: 1 | EV4: 1 | EW4: 1 | EX4: 1 | EY4: 1 | EZ4: 1 | FA4: 1 | FB4: 1 | FC4: 1 | FD4: 1 | FE4: 1 | FF4: 1 | FG4: 1 | FH4: 1 | FI4: 1 | FJ4: 1 | FK4: 1 | FL4: 1 | FM4: 1 | FN4: 1 | FO4: 1 | FP4: 1 | FQ4: 1 | FR4: 1 | FS4: 1 | FT4: 1 | FU4: 1 | FV4: 1 | FW4: 1 | FX4: 1 | FY4: 1 | FZ4: 1 | GA4: 1 | GB4: 1 | GC4: 1 | GD4: 1 | GE4: 1 | GF4: 1 | GG4: 1 | GH4: 1
C5: PIU Master | F5: 0 | G5: 62 | I5: =G5+H5 -> 62 | J5: 1 | K5: 1 | L5: 1 | M5: 1 | N5: 1 | O5: 1 | P5: 1 | Q5: 1 | R5: 1 | S5: 1 | T5: 1 | U5: 1 | V5: 1 | W5: 1 | X5: 1 | Y5: 1 | Z5: 1 | AA5: 1 | AB5: 1 | AC5: 1 | AD5: 1 | AE5: 1 | AF5: 1 | AG5: 1 | AH5: 1 | AI5: 1 | AJ5: 1 | AK5: 1 | AL5: 1 | AM5: 1 | AN5: 1 | AO5: 1 | AP5: 1 | AQ5: 1 | AR5: 1 | AS5: 1 | AT5: 1 | AU5: 1 | AV5: 1 | AW5: 1 | AX5: 1 | AY5: 1 | AZ5: 1 | BA5: 1 | BB5: 1 | BC5: 1 | BD5: 1 | BE5: 1 | BF5: 1 | BG5: 1 | BH5: 1 | BI5: 1 | BJ5: 1 | BK5: 1 | BL5: 1 | BM5: 1 | BN5: 1 | BO5: 1 | BP5: 1 | BQ5: 1 | BR5: 1 | BS5: 1 | BT5: 1 | BU5: 1 | BV5: 1 | BW5: 1 | BX5: 1 | BY5: 1 | BZ5: 1 | CA5: 1 | CB5: 1 | CC5: 1 | CD5: 1 | CE5: 1 | CF5: 1 | CG5: 1 | CH5: 1 | CI5: 1 | CJ5: 1 | CK5: 1 | CL5: 1 | CM5: 1 | CN5: 1 | CO5: 1 | CP5: 1 | CQ5: 1 | CR5: 1 | CS5: 1 | CT5: 1 | CU5: 1 | CV5: 1 | CW5: 1 | CX5: 1 | CY5: 1 | CZ5: 1 | DA5: 1 | DB5: 1 | DC5: 1 | DD5: 1 | DE5: 1 | DF5: 1 | DG5: 1 | DH5: 1 | DI5: 1 | DJ5: 1 | DK5: 1 | DL5: 1 | DM5: 1 | DN5: 1 | DO5: 1 | DP5: 1 | DQ5: 1 | DR5: 1 | DS5: 1 | DT5: 1 | DU5: 1 | DV5: 1 | DW5: 1 | DX5: 1 | DY5: 1 | DZ5: 1 | EA5: 1 | EB5: 1 | EC5: 1 | ED5: 1 | EE5: 1 | EF5: 1 | EG5: 1 | EH5: 1 | EI5: 1 | EJ5: 1 | EK5: 1 | EL5: 1 | EM5: 1 | EN5: 1 | EO5: 1 | EP5: 1 | EQ5: 1 | ER5: 1 | ES5: 1 | ET5: 1 | EU5: 1 | EV5: 1 | EW5: 1 | EX5: 1 | EY5: 1 | EZ5: 1 | FA5: 1 | FB5: 1 | FC5: 1 | FD5: 1 | FE5: 1 | FF5: 1 | FG5: 1 | FH5: 1 | FI5: 1 | FJ5: 1 | FK5: 1 | FL5: 1 | FM5: 1 | FN5: 1 | FO5: 1 | FP5: 1 | FQ5: 1 | FR5: 1 | FS5: 1 | FT5: 1 | FU5: 1 | FV5: 1 | FW5: 1 | FX5: 1 | FY5: 1 | FZ5: 1 | GA5: 1 | GB5: 1 | GC5: 1 | GD5: 1 | GE5: 1 | GF5: 1 | GG5: 1 | GH5: 1
C6: PIU Sub Cabin | F6: 0 | G6: 63 | I6: =G6+H6 -> 63 | J6: 1 | K6: 1 | L6: 1 | M6: 1 | N6: 1 | O6: 1 | P6: 1 | Q6: 1 | R6: 1 | S6: 1 | T6: 1 | U6: 1 | V6: 1 | W6: 1 | X6: 1 | Y6: 1 | Z6: 1 | AA6: 1 | AB6: 1 | AC6: 1 | AD6: 1 | AE6: 1 | AF6: 1 | AG6: 1 | AH6: 1 | AI6: 1 | AJ6: 1 | AK6: 1 | AL6: 1 | AM6: 1 | AN6: 1 | AO6: 1 | AP6: 1 | AQ6: 1 | AR6: 1 | AS6: 1 | AT6: 1 | AU6: 1 | AV6: 1 | AW6: 1 | AX6: 1 | AY6: 1 | AZ6: 1 | BA6: 1 | BB6: 1 | BC6: 1 | BD6: 1 | BE6: 1 | BF6: 1 | BG6: 1 | BH6: 1 | BI6: 1 | BJ6: 1 | BK6: 1 | BL6: 1 | BM6: 1 | BN6: 1 | BO6: 1 | BP6: 1 | BQ6: 1 | BR6: 1 | BS6: 1 | BT6: 1 | BU6: 1 | BV6: 1 | BW6: 1 | BX6: 1 | BY6: 1 | BZ6: 1 | CA6: 1 | CB6: 1 | CC6: 1 | CD6: 1 | CE6: 1 | CF6: 1 | CG6: 1 | CH6: 1 | CI6: 1 | CJ6: 1 | CK6: 1 | CL6: 1 | CM6: 1 | CN6: 1 | CO6: 1 | CP6: 1 | CQ6: 1 | CR6: 1 | CS6: 1 | CT6: 1 | CU6: 1 | CV6: 1 | CW6: 1 | CX6: 1 | CY6: 1 | CZ6: 1 | DA6: 1 | DB6: 1 | DC6: 1 | DD6: 1 | DE6: 1 | DF6: 1 | DG6: 1 | DH6: 1 | DI6: 1 | DJ6: 1 | DK6: 1 | DL6: 1 | DM6: 1 | DN6: 1 | DO6: 1 | DP6: 1 | DQ6: 1 | DR6: 1 | DS6: 1 | DT6: 1 | DU6: 1 | DV6: 1 | DW6: 1 | DX6: 1 | DY6: 1 | DZ6: 1 | EA6: 1 | EB6: 1 | EC6: 1 | ED6: 1 | EE6: 1 | EF6: 1 | EG6: 1 | EH6: 1 | EI6: 1 | EJ6: 1 | EK6: 1 | EL6: 1 | EM6: 1 | EN6: 1 | EO6: 1 | EP6: 1 | EQ6: 1 | ER6: 1 | ES6: 1 | ET6: 1 | EU6: 1 | EV6: 1 | EW6: 1 | EX6: 1 | EY6: 1 | EZ6: 1 | FA6: 1 | FB6: 1 | FC6: 1 | FD6: 1 | FE6: 1 | FF6: 1 | FG6: 1 | FH6: 1 | FI6: 1 | FJ6: 1 | FK6: 1 | FL6: 1 | FM6: 1 | FN6: 1 | FO6: 1 | FP6: 1 | FQ6: 1 | FR6: 1 | FS6: 1 | FT6: 1 | FU6: 1 | FV6: 1 | FW6: 1 | FX6: 1 | FY6: 1 | FZ6: 1 | GA6: 1 | GB6: 1 | GC6: 1 | GD6: 1 | GE6: 1 | GF6: 1 | GG6: 1 | GH6: 1
C7: PIU Hood | F7: 0 | G7: 64 | I7: =G7+H7 -> 64 | J7: 1 | K7: 1 | L7: 1 | M7: 1 | N7: 1 | O7: 1 | P7: 1 | Q7: 1 | R7: 1 | S7: 1 | T7: 1 | U7: 1 | V7: 1 | W7: 1 | X7: 1 | Y7: 1 | Z7: 1 | AA7: 1 | AB7: 1 | AC7: 1 | AD7: 1 | AE7: 1 | AF7: 1 | AG7: 1 | AH7: 1 | AI7: 1 | AJ7: 1 | AK7: 1 | AL7: 1 | AM7: 1 | AN7: 1 | AO7: 1 | AP7: 1 | AQ7: 1 | AR7: 1 | AS7: 1 | AT7: 1 | AU7: 1 | AV7: 1 | AW7: 1 | AX7: 1 | AY7: 1 | AZ7: 1 | BA7: 1 | BB7: 1 | BC7: 1 | BD7: 1 | BE7: 1 | BF7: 1 | BG7: 1 | BH7: 1 | BI7: 1 | BJ7: 1 | BK7: 1 | BL7: 1 | BM7: 1 | BN7: 1 | BO7: 1 | BP7: 1 | BQ7: 1 | BR7: 1 | BS7: 1 | BT7: 1 | BU7: 1 | BV7: 1 | BW7: 1 | BX7: 1 | BY7: 1 | BZ7: 1 | CA7: 1 | CB7: 1 | CC7: 1 | CD7: 1 | CE7: 1 | CF7: 1 | CG7: 1 | CH7: 1 | CI7: 1 | CJ7: 1 | CK7: 1 | CL7: 1 | CM7: 1 | CN7: 1 | CO7: 1 | CP7: 1 | CQ7: 1 | CR7: 1 | CS7: 1 | CT7: 1 | CU7: 1 | CV7: 1 | CW7: 1 | CX7: 1 | CY7: 1 | CZ7: 1 | DA7: 1 | DB7: 1 | DC7: 1 | DD7: 1 | DE7: 1 | DF7: 1 | DG7: 1 | DH7: 1 | DI7: 1 | DJ7: 1 | DK7: 1 | DL7: 1 | DM7: 1 | DN7: 1 | DO7: 1 | DP7: 1 | DQ7: 1 | DR7: 1 | DS7: 1 | DT7: 1 | DU7: 1 | DV7: 1 | DW7: 1 | DX7: 1 | DY7: 1 | DZ7: 1 | EA7: 1 | EB7: 1 | EC7: 1 | ED7: 1 | EE7: 1 | EF7: 1 | EG7: 1 | EH7: 1 | EI7: 1 | EJ7: 1 | EK7: 1 | EL7: 1 | EM7: 1 | EN7: 1 | EO7: 1 | EP7: 1 | EQ7: 1 | ER7: 1 | ES7: 1 | ET7: 1 | EU7: 1 | EV7: 1 | EW7: 1 | EX7: 1 | EY7: 1 | EZ7: 1 | FA7: 1 | FB7: 1 | FC7: 1 | FD7: 1 | FE7: 1 | FF7: 1 | FG7: 1 | FH7: 1 | FI7: 1 | FJ7: 1 | FK7: 1 | FL7: 1 | FM7: 1 | FN7: 1 | FO7: 1 | FP7: 1 | FQ7: 1 | FR7: 1 | FS7: 1 | FT7: 1 | FU7: 1 | FV7: 1 | FW7: 1 | FX7: 1 | FY7: 1 | FZ7: 1 | GA7: 1 | GB7: 1 | GC7: 1 | GD7: 1 | GE7: 1 | GF7: 1 | GG7: 1 | GH7: 1
C8: DSM Power Parking | G8: 65 | I8: =G8+H8 -> 65 | J8: 1 | K8: 1 | L8: 1 | M8: 1 | N8: 1 | O8: 1 | P8: 1 | Q8: 1 | R8: 1 | S8: 1 | T8: 1 | U8: 1 | V8: 1 | W8: 1 | X8: 1 | Y8: 1 | Z8: 1 | AA8: 1 | AB8: 1 | AC8: 1 | AD8: 1 | AE8: 1 | AF8: 1 | AG8: 1 | AH8: 1 | AI8: 1 | AJ8: 1 | AK8: 1 | AL8: 1 | AM8: 1 | AN8: 1 | AO8: 1 | AP8: 1 | AQ8: 1 | AR8: 1 | AS8: 1 | AT8: 1 | AU8: 1 | AV8: 1 | AW8: 1 | AX8: 1 | AY8: 1 | AZ8: 1 | BA8: 1 | BB8: 1 | BC8: 1 | BD8: 1 | BE8: 1 | BF8: 1 | BG8: 1 | BH8: 1 | BI8: 1 | BJ8: 1 | BK8: 1 | BL8: 1 | BM8: 1 | BN8: 1 | BO8: 1 | BP8: 1 | BQ8: 1 | BR8: 1 | BS8: 1 | BT8: 1 | BU8: 1 | BV8: 1 | BW8: 1 | BX8: 1 | BY8: 1 | BZ8: 1 | CA8: 1 | CB8: 1 | CC8: 1 | CD8: 1 | CE8: 1 | CF8: 1 | CG8: 1 | CH8: 1 | CI8: 1 | CJ8: 1 | CK8: 1 | CL8: 1 | CM8: 1 | CN8: 1 | CO8: 1 | CP8: 1 | CQ8: 1 | CR8: 1 | CS8: 1 | CT8: 1 | CU8: 1 | CV8: 1 | CW8: 1 | CX8: 1 | CY8: 1 | CZ8: 1 | DA8: 1 | DB8: 1 | DC8: 1 | DD8: 1 | DE8: 1 | DF8: 1 | DG8: 1 | DH8: 1 | DI8: 1 | DJ8: 1 | DK8: 1 | DL8: 1 | DM8: 1 | DN8: 1 | DO8: 1 | DP8: 1 | DQ8: 1 | DR8: 1 | DS8: 1 | DT8: 1 | DU8: 1 | DV8: 1 | DW8: 1 | DX8: 1 | DY8: 1 | DZ8: 1 | EA8: 1 | EB8: 1 | EC8: 1 | ED8: 1 | EE8: 1 | EF8: 1 | EG8: 1 | EH8: 1 | EI8: 1 | EJ8: 1 | EK8: 1 | EL8: 1 | EM8: 1 | EN8: 1 | EO8: 1 | EP8: 1 | EQ8: 1 | ER8: 1 | ES8: 1 | ET8: 1 | EU8: 1 | EV8: 1 | EW8: 1 | EX8: 1 | EY8: 1 | EZ8: 1 | FA8: 1 | FB8: 1 | FC8: 1 | FD8: 1 | FE8: 1 | FF8: 1 | FG8: 1 | FH8: 1 | FI8: 1 | FJ8: 1 | FK8: 1 | FL8: 1 | FM8: 1 | FN8: 1 | FO8: 1 | FP8: 1 | FQ8: 1 | FR8: 1 | FS8: 1 | FT8: 1 | FU8: 1 | FV8: 1 | FW8: 1 | FX8: 1 | FY8: 1 | FZ8: 1 | GA8: 1 | GB8: 1 | GC8: 1 | GD8: 1 | GE8: 1 | GF8: 1 | GG8: 1 | GH8: 1
C9: DSM Power Adapation | G9: 66 | I9: =G9+H9 -> 66 | J9: 1 | K9: 1 | L9: 1 | M9: 1 | N9: 1 | O9: 1 | P9: 1 | Q9: 1 | R9: 1 | S9: 1 | T9: 1 | U9: 1 | V9: 1 | W9: 1 | X9: 1 | Y9: 1 | Z9: 1 | AA9: 1 | AB9: 1 | AC9: 1 | AD9: 1 | AE9: 1 | AF9: 1 | AG9: 1 | AH9: 1 | AI9: 1 | AJ9: 1 | AK9: 1 | AL9: 1 | AM9: 1 | AN9: 1 | AO9: 1 | AP9: 1 | AQ9: 1 | AR9: 1 | AS9: 1 | AT9: 1 | AU9: 1 | AV9: 1 | AW9: 1 | AX9: 1 | AY9: 1 | AZ9: 1 | BA9: 1 | BB9: 1 | BC9: 1 | BD9: 1 | BE9: 1 | BF9: 1 | BG9: 1 | BH9: 1 | BI9: 1 | BJ9: 1 | BK9: 1 | BL9: 1 | BM9: 1 | BN9: 1 | BO9: 1 | BP9: 1 | BQ9: 1 | BR9: 1 | BS9: 1 | BT9: 1 | BU9: 1 | BV9: 1 | BW9: 1 | BX9: 1 | BY9: 1 | BZ9: 1 | CA9: 1 | CB9: 1 | CC9: 1 | CD9: 1 | CE9: 1 | CF9: 1 | CG9: 1 | CH9: 1 | CI9: 1 | CJ9: 1 | CK9: 1 | CL9: 1 | CM9: 1 | CN9: 1 | CO9: 1 | CP9: 1 | CQ9: 1 | CR9: 1 | CS9: 1 | CT9: 1 | CU9: 1 | CV9: 1 | CW9: 1 | CX9: 1 | CY9: 1 | CZ9: 1 | DA9: 1 | DB9: 1 | DC9: 1 | DD9: 1 | DE9: 1 | DF9: 1 | DG9: 1 | DH9: 1 | DI9: 1 | DJ9: 1 | DK9: 1 | DL9: 1 | DM9: 1 | DN9: 1 | DO9: 1 | DP9: 1 | DQ9: 1 | DR9: 1 | DS9: 1 | DT9: 1 | DU9: 1 | DV9: 1 | DW9: 1 | DX9: 1 | DY9: 1 | DZ9: 1 | EA9: 1 | EB9: 1 | EC9: 1 | ED9: 1 | EE9: 1 | EF9: 1 | EG9: 1 | EH9: 1 | EI9: 1 | EJ9: 1 | EK9: 1 | EL9: 1 | EM9: 1 | EN9: 1 | EO9: 1 | EP9: 1 | EQ9: 1 | ER9: 1 | ES9: 1 | ET9: 1 | EU9: 1 | EV9: 1 | EW9: 1 | EX9: 1 | EY9: 1 | EZ9: 1 | FA9: 1 | FB9: 1 | FC9: 1 | FD9: 1 | FE9: 1 | FF9: 1 | FG9: 1 | FH9: 1 | FI9: 1 | FJ9: 1 | FK9: 1 | FL9: 1 | FM9: 1 | FN9: 1 | FO9: 1 | FP9: 1 | FQ9: 1 | FR9: 1 | FS9: 1 | FT9: 1 | FU9: 1 | FV9: 1 | FW9: 1 | FX9: 1 | FY9: 1 | FZ9: 1 | GA9: 1 | GB9: 1 | GC9: 1 | GD9: 1 | GE9: 1 | GF9: 1 | GG9: 1 | GH9: 1
C10: DSM Winter | G10: 67 | I10: =G10+H10 -> 67 | J10: 1 | K10: 1 | L10: 1 | M10: 1 | N10: 1 | O10: 1 | P10: 1 | Q10: 1 | R10: 1 | S10: 1 | T10: 1 | U10: 1 | V10: 1 | W10: 1 | X10: 1 | Y10: 1 | Z10: 1 | AA10: 1 | AB10: 1 | AC10: 1 | AD10: 1 | AE10: 1 | AF10: 1 | AG10: 1 | AH10: 1 | AI10: 1 | AJ10: 1 | AK10: 1 | AL10: 1 | AM10: 1 | AN10: 1 | AO10: 1 | AP10: 1 | AQ10: 1 | AR10: 1 | AS10: 1 | AT10: 1 | AU10: 1 | AV10: 1 | AW10: 1 | AX10: 1 | AY10: 1 | AZ10: 1 | BA10: 1 | BB10: 1 | BC10: 1 | BD10: 1 | BE10: 1 | BF10: 1 | BG10: 1 | BH10: 1 | BI10: 1 | BJ10: 1 | BK10: 1 | BL10: 1 | BM10: 1 | BN10: 1 | BO10: 1 | BP10: 1 | BQ10: 1 | BR10: 1 | BS10: 1 | BT10: 1 | BU10: 1 | BV10: 1 | BW10: 1 | BX10: 1 | BY10: 1 | BZ10: 1 | CA10: 1 | CB10: 1 | CC10: 1 | CD10: 1 | CE10: 1 | CF10: 1 | CG10: 1 | CH10: 1 | CI10: 1 | CJ10: 1 | CK10: 1 | CL10: 1 | CM10: 1 | CN10: 1 | CO10: 1 | CP10: 1 | CQ10: 1 | CR10: 1 | CS10: 1 | CT10: 1 | CU10: 1 | CV10: 1 | CW10: 1 | CX10: 1 | CY10: 1 | CZ10: 1 | DA10: 1 | DB10: 1 | DC10: 1 | DD10: 1 | DE10: 1 | DF10: 1 | DG10: 1 | DH10: 1 | DI10: 1 | DJ10: 1 | DK10: 1 | DL10: 1 | DM10: 1 | DN10: 1 | DO10: 1 | DP10: 1 | DQ10: 1 | DR10: 1 | DS10: 1 | DT10: 1 | DU10: 1 | DV10: 1 | DW10: 1 | DX10: 1 | DY10: 1 | DZ10: 1 | EA10: 1 | EB10: 1 | EC10: 1 | ED10: 1 | EE10: 1 | EF10: 1 | EG10: 1 | EH10: 1 | EI10: 1 | EJ10: 1 | EK10: 1 | EL10: 1 | EM10: 1 | EN10: 1 | EO10: 1 | EP10: 1 | EQ10: 1 | ER10: 1 | ES10: 1 | ET10: 1 | EU10: 1 | EV10: 1 | EW10: 1 | EX10: 1 | EY10: 1 | EZ10: 1 | FA10: 1 | FB10: 1 | FC10: 1 | FD10: 1 | FE10: 1 | FF10: 1 | FG10: 1 | FH10: 1 | FI10: 1 | FJ10: 1 | FK10: 1 | FL10: 1 | FM10: 1 | FN10: 1 | FO10: 1 | FP10: 1 | FQ10: 1 | FR10: 1 | FS10: 1 | FT10: 1 | FU10: 1 | FV10: 1 | FW10: 1 | FX10: 1 | FY10: 1 | FZ10: 1 | GA10: 1 | GB10: 1 | GC10: 1 | GD10: 1 | GE10: 1 | GF10: 1 | GG10: 1 | GH10: 1
C11: DSM H2 | G11: 68 | I11: =G11+H11 -> 68 | J11: 1 | K11: 1 | L11: 1 | M11: 1 | N11: 1 | O11: 1 | P11: 1 | Q11: 1 | R11: 1 | S11: 1 | T11: 1 | U11: 1 | V11: 1 | W11: 1 | X11: 1 | Y11: 1 | Z11: 1 | AA11: 1 | AB11: 1 | AC11: 1 | AD11: 1 | AE11: 1 | AF11: 1 | AG11: 1 | AH11: 1 | AI11: 1 | AJ11: 1 | AK11: 1 | AL11: 1 | AM11: 1 | AN11: 1 | AO11: 1 | AP11: 1 | AQ11: 1 | AR11: 1 | AS11: 1 | AT11: 1 | AU11: 1 | AV11: 1 | AW11: 1 | AX11: 1 | AY11: 1 | AZ11: 1 | BA11: 1 | BB11: 1 | BC11: 1 | BD11: 1 | BE11: 1 | BF11: 1 | BG11: 1 | BH11: 1 | BI11: 1 | BJ11: 1 | BK11: 1 | BL11: 1 | BM11: 1 | BN11: 1 | BO11: 1 | BP11: 1 | BQ11: 1 | BR11: 1 | BS11: 1 | BT11: 1 | BU11: 1 | BV11: 1 | BW11: 1 | BX11: 1 | BY11: 1 | BZ11: 1 | CA11: 1 | CB11: 1 | CC11: 1 | CD11: 1 | CE11: 1 | CF11: 1 | CG11: 1 | CH11: 1 | CI11: 1 | CJ11: 1 | CK11: 1 | CL11: 1 | CM11: 1 | CN11: 1 | CO11: 1 | CP11: 1 | CQ11: 1 | CR11: 1 | CS11: 1 | CT11: 1 | CU11: 1 | CV11: 1 | CW11: 1 | CX11: 1 | CY11: 1 | CZ11: 1 | DA11: 1 | DB11: 1 | DC11: 1 | DD11: 1 | DE11: 1 | DF11: 1 | DG11: 1 | DH11: 1 | DI11: 1 | DJ11: 1 | DK11: 1 | DL11: 1 | DM11: 1 | DN11: 1 | DO11: 1 | DP11: 1 | DQ11: 1 | DR11: 1 | DS11: 1 | DT11: 1 | DU11: 1 | DV11: 1 | DW11: 1 | DX11: 1 | DY11: 1 | DZ11: 1 | EA11: 1 | EB11: 1 | EC11: 1 | ED11: 1 | EE11: 1 | EF11: 1 | EG11: 1 | EH11: 1 | EI11: 1 | EJ11: 1 | EK11: 1 | EL11: 1 | EM11: 1 | EN11: 1 | EO11: 1 | EP11: 1 | EQ11: 1 | ER11: 1 | ES11: 1 | ET11: 1 | EU11: 1 | EV11: 1 | EW11: 1 | EX11: 1 | EY11: 1 | EZ11: 1 | FA11: 1 | FB11: 1 | FC11: 1 | FD11: 1 | FE11: 1 | FF11: 1 | FG11: 1 | FH11: 1 | FI11: 1 | FJ11: 1 | FK11: 1 | FL11: 1 | FM11: 1 | FN11: 1 | FO11: 1 | FP11: 1 | FQ11: 1 | FR11: 1 | FS11: 1 | FT11: 1 | FU11: 1 | FV11: 1 | FW11: 1 | FX11: 1 | FY11: 1 | FZ11: 1 | GA11: 1 | GB11: 1 | GC11: 1 | GD11: 1 | GE11: 1 | GF11: 1 | GG11: 1 | GH11: 1
C12: DSM Trailer | G12: 69 | I12: =G12+H12 -> 69 | J12: 1 | K12: 1 | L12: 1 | M12: 1 | N12: 1 | O12: 1 | P12: 1 | Q12: 1 | R12: 1 | S12: 1 | T12: 1 | U12: 1 | V12: 1 | W12: 1 | X12: 1 | Y12: 1 | Z12: 1 | AA12: 1 | AB12: 1 | AC12: 1 | AD12: 1 | AE12: 1 | AF12: 1 | AG12: 1 | AH12: 1 | AI12: 1 | AJ12: 1 | AK12: 1 | AL12: 1 | AM12: 1 | AN12: 1 | AO12: 1 | AP12: 1 | AQ12: 1 | AR12: 1 | AS12: 1 | AT12: 1 | AU12: 1 | AV12: 1 | AW12: 1 | AX12: 1 | AY12: 1 | AZ12: 1 | BA12: 1 | BB12: 1 | BC12: 1 | BD12: 1 | BE12: 1 | BF12: 1 | BG12: 1 | BH12: 1 | BI12: 1 | BJ12: 1 | BK12: 1 | BL12: 1 | BM12: 1 | BN12: 1 | BO12: 1 | BP12: 1 | BQ12: 1 | BR12: 1 | BS12: 1 | BT12: 1 | BU12: 1 | BV12: 1 | BW12: 1 | BX12: 1 | BY12: 1 | BZ12: 1 | CA12: 1 | CB12: 1 | CC12: 1 | CD12: 1 | CE12: 1 | CF12: 1 | CG12: 1 | CH12: 1 | CI12: 1 | CJ12: 1 | CK12: 1 | CL12: 1 | CM12: 1 | CN12: 1 | CO12: 1 | CP12: 1 | CQ12: 1 | CR12: 1 | CS12: 1 | CT12: 1 | CU12: 1 | CV12: 1 | CW12: 1 | CX12: 1 | CY12: 1 | CZ12: 1 | DA12: 1 | DB12: 1 | DC12: 1 | DD12: 1 | DE12: 1 | DF12: 1 | DG12: 1 | DH12: 1 | DI12: 1 | DJ12: 1 | DK12: 1 | DL12: 1 | DM12: 1 | DN12: 1 | DO12: 1 | DP12: 1 | DQ12: 1 | DR12: 1 | DS12: 1 | DT12: 1 | DU12: 1 | DV12: 1 | DW12: 1 | DX12: 1 | DY12: 1 | DZ12: 1 | EA12: 1 | EB12: 1 | EC12: 1 | ED12: 1 | EE12: 1 | EF12: 1 | EG12: 1 | EH12: 1 | EI12: 1 | EJ12: 1 | EK12: 1 | EL12: 1 | EM12: 1 | EN12: 1 | EO12: 1 | EP12: 1 | EQ12: 1 | ER12: 1 | ES12: 1 | ET12: 1 | EU12: 1 | EV12: 1 | EW12: 1 | EX12: 1 | EY12: 1 | EZ12: 1 | FA12: 1 | FB12: 1 | FC12: 1 | FD12: 1 | FE12: 1 | FF12: 1 | FG12: 1 | FH12: 1 | FI12: 1 | FJ12: 1 | FK12: 1 | FL12: 1 | FM12: 1 | FN12: 1 | FO12: 1 | FP12: 1 | FQ12: 1 | FR12: 1 | FS12: 1 | FT12: 1 | FU12: 1 | FV12: 1 | FW12: 1 | FX12: 1 | FY12: 1 | FZ12: 1 | GA12: 1 | GB12: 1 | GC12: 1 | GD12: 1 | GE12: 1 | GF12: 1 | GG12: 1 | GH12: 1
B13: 2637 | C13: DCDC | D13: DCDC | F13: 0 | G13: 70 | H13: 0 | I13: =G13+H13 -> 70 | J13: 1 | K13: 1 | L13: 1 | M13: 1 | N13: 1 | O13: 1 | P13: 1 | Q13: 1 | R13: 1 | S13: 1 | T13: 1 | U13: 1 | V13: 1 | W13: 1 | X13: 1 | Y13: 1 | Z13: 1 | AA13: 1 | AB13: 1 | AC13: 1 | AD13: 1 | AE13: 1 | AF13: 1 | AG13: 1 | AH13: 1 | AI13: 1 | AJ13: 1 | AK13: 1 | AL13: 1 | AM13: 1 | AN13: 1 | AO13: 1 | AP13: 1 | AQ13: 1 | AR13: 1 | AS13: 1 | AT13: 1 | AU13: 1 | AV13: 1 | AW13: 1 | AX13: 1 | AY13: 1 | AZ13: 1 | BA13: 1 | BB13: 1 | BC13: 1 | BD13: 1 | BE13: 1 | BF13: 1 | BG13: 1 | BH13: 1 | BI13: 1 | BJ13: 1 | BK13: 1 | BL13: 1 | BM13: 1 | BN13: 1 | BO13: 1 | BP13: 1 | BQ13: 1 | BR13: 1 | BS13: 1 | BT13: 1 | BU13: 1 | BV13: 1 | BW13: 1 | BX13: 1 | BY13: 1 | BZ13: 1 | CA13: 1 | CB13: 1 | CC13: 1 | CD13: 1 | CE13: 1 | CF13: 1 | CG13: 1 | CH13: 1 | CI13: 1 | CJ13: 1 | CK13: 1 | CL13: 1 | CM13: 1 | CN13: 1 | CO13: 1 | CP13: 1 | CQ13: 1 | CR13: 1 | CS13: 1 | CT13: 1 | CU13: 1 | CV13: 1 | CW13: 1 | CX13: 1 | CY13: 1 | CZ13: 1 | DA13: 1 | DB13: 1 | DC13: 1 | DD13: 1 | DE13: 1 | DF13: 1 | DG13: 1 | DH13: 1 | DI13: 1 | DJ13: 1 | DK13: 1 | DL13: 1 | DM13: 1 | DN13: 1 | DO13: 1 | DP13: 1 | DQ13: 1 | DR13: 1 | DS13: 1 | DT13: 1 | DU13: 1 | DV13: 1 | DW13: 1 | DX13: 1 | DY13: 1 | DZ13: 1 | EA13: 1 | EB13: 1 | EC13: 1 | ED13: 1 | EE13: 1 | EF13: 1 | EG13: 1 | EH13: 1 | EI13: 1 | EJ13: 1 | EK13: 1 | EL13: 1 | EM13: 1 | EN13: 1 | EO13: 1 | EP13: 1 | EQ13: 1 | ER13: 1 | ES13: 1 | ET13: 1 | EU13: 1 | EV13: 1 | EW13: 1 | EX13: 1 | EY13: 1 | EZ13: 1 | FA13: 1 | FB13: 1 | FC13: 1 | FD13: 1 | FE13: 1 | FF13: 1 | FG13: 1 | FH13: 1 | FI13: 1 | FJ13: 1 | FK13: 1 | FL13: 1 | FM13: 1 | FN13: 1 | FO13: 1 | FP13: 1 | FQ13: 1 | FR13: 1 | FS13: 1 | FT13: 1 | FU13: 1 | FV13: 1 | FW13: 1 | FX13: 1 | FY13: 1 | FZ13: 1 | GA13: 1 | GB13: 1 | GC13: 1 | GD13: 1 | GE13: 1 | GF13: 1 | GG13: 1 | GH13: 1
A14: S20 Electrical Energy Storage for traction | B14: 2656 | C14: BMS MAIN MONITORING TRACTION BATTERY HIGH VOLTAGE | D14: BMS/BMS2 power supply | E14: Cust : if 12V Bat OK | F14: 0 | G14: 71 | H14: 0 | I14: =G14+H14 -> 71 | J14: 1 | K14: 1 | L14: 1 | M14: 1 | N14: 1 | O14: 1 | P14: 1 | Q14: 1 | R14: 1 | S14: 1 | T14: 1 | U14: 1 | V14: 1 | W14: 1 | X14: 1 | Y14: 1 | Z14: 1 | AA14: 1 | AB14: 1 | AC14: 1 | AD14: 1 | AE14: 1 | AF14: 1 | AG14: 1 | AH14: 1 | AI14: 1 | AJ14: 1 | AK14: 1 | AL14: 1 | AM14: 1 | AN14: 1 | AO14: 1 | AP14: 1 | AQ14: 1 | AR14: 1 | AS14: 1 | AT14: 1 | AU14: 1 | AV14: 1 | AW14: 1 | AX14: 1 | AY14: 1 | AZ14: 1 | BA14: 1 | BB14: 1 | BC14: 1 | BD14: 1 | BE14: 1 | BF14: 1 | BG14: 1 | BH14: 1 | BI14: 1 | BJ14: 1 | BK14: 1 | BL14: 1 | BM14: 1 | BN14: 1 | BO14: 1 | BP14: 1 | BQ14: 1 | BR14: 1 | BS14: 1 | BT14: 1 | BU14: 1 | BV14: 1 | BW14: 1 | BX14: 1 | BY14: 1 | BZ14: 1 | CA14: 1 | CB14: 1 | CC14: 1 | CD14: 1 | CE14: 1 | CF14: 1 | CG14: 1 | CH14: 1 | CI14: 1 | CJ14: 1 | CK14: 1 | CL14: 1 | CM14: 1 | CN14: 1 | CO14: 1 | CP14: 1 | CQ14: 1 | CR14: 1 | CS14: 1 | CT14: 1 | CU14: 1 | CV14: 1 | CW14: 1 | CX14: 1 | CY14: 1 | CZ14: 1 | DA14: 1 | DB14: 1 | DC14: 1 | DD14: 1 | DE14: 1 | DF14: 1 | DG14: 1 | DH14: 1 | DI14: 1 | DJ14: 1 | DK14: 1 | DL14: 1 | DM14: 1 | DN14: 1 | DO14: 1 | DP14: 1 | DQ14: 1 | DR14: 1 | DS14: 1 | DT14: 1 | DU14: 1 | DV14: 1 | DW14: 1 | DX14: 1 | DY14: 1 | DZ14: 1 | EA14: 1 | EB14: 1 | EC14: 1 | ED14: 1 | EE14: 1 | EF14: 1 | EG14: 1 | EH14: 1 | EI14: 1 | EJ14: 1 | EK14: 1 | EL14: 1 | EM14: 1 | EN14: 1 | EO14: 1 | EP14: 1 | EQ14: 1 | ER14: 1 | ES14: 1 | ET14: 1 | EU14: 1 | EV14: 1 | EW14: 1 | EX14: 1 | EY14: 1 | EZ14: 1 | FA14: 1 | FB14: 1 | FC14: 1 | FD14: 1 | FE14: 1 | FF14: 1 | FG14: 1 | FH14: 1 | FI14: 1 | FJ14: 1 | FK14: 1 | FL14: 1 | FM14: 1 | FN14: 1 | FO14: 1 | FP14: 1 | FQ14: 1 | FR14: 1 | FS14: 1 | FT14: 1 | FU14: 1 | FV14: 1 | FW14: 1 | FX14: 1 | FY14: 1 | FZ14: 1 | GA14: 1 | GB14: 1 | GC14: 1 | GD14: 1 | GE14: 1 | GF14: 1 | GG14: 1 | GH14: 1
A15: S53 Power Distribution | B15: 2990 | C15: PCU PHYSICAL COMPUTING UNIT | D15: Main Microcontroller | F15: 0 | G15: 72 | H15: 0 | I15: =G15+H15 -> 72 | J15: 1 | K15: 1 | L15: 1 | M15: 1 | N15: 1 | O15: 1 | P15: 1 | Q15: 1 | R15: 1 | S15: 1 | T15: 1 | U15: 1 | V15: 1 | W15: 1 | X15: 1 | Y15: 1 | Z15: 1 | AA15: 1 | AB15: 1 | AC15: 1 | AD15: 1 | AE15: 1 | AF15: 1 | AG15: 1 | AH15: 1 | AI15: 1 | AJ15: 1 | AK15: 1 | AL15: 1 | AM15: 1 | AN15: 1 | AO15: 1 | AP15: 1 | AQ15: 1 | AR15: 1 | AS15: 1 | AT15: 1 | AU15: 1 | AV15: 1 | AW15: 1 | AX15: 1 | AY15: 1 | AZ15: 1 | BA15: 1 | BB15: 1 | BC15: 1 | BD15: 1 | BE15: 1 | BF15: 1 | BG15: 1 | BH15: 1 | BI15: 1 | BJ15: 1 | BK15: 1 | BL15: 1 | BM15: 1 | BN15: 1 | BO15: 1 | BP15: 1 | BQ15: 1 | BR15: 1 | BS15: 1 | BT15: 1 | BU15: 1 | BV15: 1 | BW15: 1 | BX15: 1 | BY15: 1 | BZ15: 1 | CA15: 1 | CB15: 1 | CC15: 1 | CD15: 1 | CE15: 1 | CF15: 1 | CG15: 1 | CH15: 1 | CI15: 1 | CJ15: 1 | CK15: 1 | CL15: 1 | CM15: 1 | CN15: 1 | CO15: 1 | CP15: 1 | CQ15: 1 | CR15: 1 | CS15: 1 | CT15: 1 | CU15: 1 | CV15: 1 | CW15: 1 | CX15: 1 | CY15: 1 | CZ15: 1 | DA15: 1 | DB15: 1 | DC15: 1 | DD15: 1 | DE15: 1 | DF15: 1 | DG15: 1 | DH15: 1 | DI15: 1 | DJ15: 1 | DK15: 1 | DL15: 1 | DM15: 1 | DN15: 1 | DO15: 1 | DP15: 1 | DQ15: 1 | DR15: 1 | DS15: 1 | DT15: 1 | DU15: 1 | DV15: 1 | DW15: 1 | DX15: 1 | DY15: 1 | DZ15: 1 | EA15: 1 | EB15: 1 | EC15: 1 | ED15: 1 | EE15: 1 | EF15: 1 | EG15: 1 | EH15: 1 | EI15: 1 | EJ15: 1 | EK15: 1 | EL15: 1 | EM15: 1 | EN15: 1 | EO15: 1 | EP15: 1 | EQ15: 1 | ER15: 1 | ES15: 1 | ET15: 1 | EU15: 1 | EV15: 1 | EW15: 1 | EX15: 1 | EY15: 1 | EZ15: 1 | FA15: 1 | FB15: 1 | FC15: 1 | FD15: 1 | FE15: 1 | FF15: 1 | FG15: 1 | FH15: 1 | FI15: 1 | FJ15: 1 | FK15: 1 | FL15: 1 | FM15: 1 | FN15: 1 | FO15: 1 | FP15: 1 | FQ15: 1 | FR15: 1 | FS15: 1 | FT15: 1 | FU15: 1 | FV15: 1 | FW15: 1 | FX15: 1 | FY15: 1 | FZ15: 1 | GA15: 1 | GB15: 1 | GC15: 1 | GD15: 1 | GE15: 1 | GF15: 1 | GG15: 1 | GH15: 1
A16: S10 Braking and Electronic stability control | B16: 160 | C16: STOP LIGHT SWITCH (Normally closed for Stop Lamp) | D16: Brake pedal | E16: Cust : <12h | G16: 73 | H16: 0 | I16: =G16+H16 -> 73 | K16: 1
A17: S22 Connectivity | B17: 2152 | C17: IVC Smart Antenna | D17: IVC Smart Antenna | G17: 74 | H17: 0 | I17: =G17+H17 -> 74 | J17: 1 | K17: 1 | L17: 1 | M17: 1 | N17: 1 | O17: 1 | P17: 1 | Q17: 1 | R17: 1 | S17: 1 | T17: 1 | U17: 1 | V17: 1 | W17: 1 | X17: 1 | Y17: 1 | Z17: 1 | AA17: 1 | AB17: 1 | AC17: 1 | AD17: 1 | AE17: 1 | AF17: 1 | AG17: 1 | AH17: 1 | AI17: 1 | AJ17: 1 | AK17: 1 | AL17: 1 | AM17: 1 | AN17: 1 | AO17: 1 | AP17: 1 | AQ17: 1 | AR17: 1 | AS17: 1 | AT17: 1 | AU17: 1 | AV17: 1 | AW17: 1 | AX17: 1 | AY17: 1 | AZ17: 1 | BA17: 1 | BB17: 1 | BC17: 1 | BD17: 1 | BE17: 1 | BF17: 1 | BG17: 1 | BH17: 1 | BI17: 1 | BJ17: 1 | BK17: 1 | BL17: 1 | BM17: 1 | BN17: 1 | BO17: 1 | BP17: 1 | BQ17: 1 | BR17: 1 | BS17: 1 | BT17: 1 | BU17: 1 | BV17: 1 | BW17: 1 | BX17: 1 | BY17: 1 | BZ17: 1 | CA17: 1 | CB17: 1 | CC17: 1 | CD17: 1 | CE17: 1 | CF17: 1 | CG17: 1 | CH17: 1 | CI17: 1 | CJ17: 1 | CK17: 1 | CL17: 1 | CM17: 1 | CN17: 1 | CO17: 1 | CP17: 1 | CQ17: 1 | CR17: 1 | CS17: 1 | CT17: 1 | CU17: 1 | CV17: 1 | CW17: 1 | CX17: 1 | CY17: 1 | CZ17: 1 | DA17: 1 | DB17: 1 | DC17: 1 | DD17: 1 | DE17: 1 | DF17: 1 | DG17: 1 | DH17: 1 | DI17: 1 | DJ17: 1 | DK17: 1 | DL17: 1 | DM17: 1 | DN17: 1 | DO17: 1 | DP17: 1 | DQ17: 1 | DR17: 1 | DS17: 1 | DT17: 1 | DU17: 1 | DV17: 1 | DW17: 1 | DX17: 1 | DY17: 1 | DZ17: 1 | EA17: 1 | EB17: 1 | EC17: 1 | ED17: 1 | EE17: 1 | EF17: 1 | EG17: 1 | EH17: 1 | EI17: 1 | EJ17: 1 | EK17: 1 | EL17: 1 | EM17: 1 | EN17: 1 | EO17: 1 | EP17: 1 | EQ17: 1 | ER17: 1 | ES17: 1 | ET17: 1 | EU17: 1 | EV17: 1 | EW17: 1 | EX17: 1 | EY17: 1 | EZ17: 1 | FA17: 1 | FB17: 1 | FC17: 1 | FD17: 1 | FE17: 1 | FF17: 1 | FG17: 1 | FH17: 1 | FI17: 1 | FJ17: 1 | FK17: 1 | FL17: 1 | FM17: 1 | FN17: 1 | FO17: 1 | FP17: 1 | FQ17: 1 | FR17: 1 | FS17: 1 | FT17: 1 | FU17: 1 | FV17: 1 | FW17: 1 | FX17: 1 | FY17: 1 | FZ17: 1 | GA17: 1 | GB17: 1 | GC17: 1 | GD17: 1 | GE17: 1 | GF17: 1 | GG17: 1 | GH17: 1
A18: S22 Connectivity | B18: 2893 | C18: BLUETOOTH LOW ENERGY MODULE | D18: BLM/IDG | E18: Cust : if 12V Bat OK | G18: 75 | H18: 0 | I18: =G18+H18 -> 75 | K18: 1
A19: S28 Access and Vehicle Protection | B19: 2003 | C19: HANDS-FREE ACCESS ECU | D19: KAM | E19: Cust : if 12V Bat OK | G19: 76 | H19: 0 | I19: =G19+H19 -> 76 | J19: 1 | K19: 1 | L19: 1 | M19: 1 | N19: 1 | O19: 1 | P19: 1 | Q19: 1 | R19: 1 | S19: 1 | T19: 1 | U19: 1 | V19: 1 | W19: 1 | X19: 1 | Y19: 1 | Z19: 1 | AA19: 1 | AB19: 1 | AC19: 1 | AD19: 1 | AE19: 1 | AF19: 1 | AG19: 1 | AH19: 1 | AI19: 1 | AJ19: 1 | AK19: 1 | AL19: 1 | AM19: 1 | AN19: 1 | AO19: 1 | AP19: 1 | AQ19: 1 | AR19: 1 | AS19: 1 | AT19: 1 | AU19: 1 | AV19: 1 | AW19: 1 | AX19: 1 | AY19: 1 | AZ19: 1 | BA19: 1 | BB19: 1 | BC19: 1 | BD19: 1 | BE19: 1 | BF19: 1 | BG19: 1 | BH19: 1 | BI19: 1 | BJ19: 1 | BK19: 1 | BL19: 1 | BM19: 1 | BN19: 1 | BO19: 1 | BP19: 1 | BQ19: 1 | BR19: 1 | BS19: 1 | BT19: 1 | BU19: 1 | BV19: 1 | BW19: 1 | BX19: 1 | BY19: 1 | BZ19: 1 | CA19: 1 | CB19: 1 | CC19: 1 | CD19: 1 | CE19: 1 | CF19: 1 | CG19: 1 | CH19: 1 | CI19: 1 | CJ19: 1 | CK19: 1 | CL19: 1 | CM19: 1 | CN19: 1 | CO19: 1 | CP19: 1 | CQ19: 1 | CR19: 1 | CS19: 1 | CT19: 1 | CU19: 1 | CV19: 1 | CW19: 1 | CX19: 1 | CY19: 1 | CZ19: 1 | DA19: 1 | DB19: 1 | DC19: 1 | DD19: 1 | DE19: 1 | DF19: 1 | DG19: 1 | DH19: 1 | DI19: 1 | DJ19: 1 | DK19: 1 | DL19: 1 | DM19: 1 | DN19: 1 | DO19: 1 | DP19: 1 | DQ19: 1 | DR19: 1 | DS19: 1 | DT19: 1 | DU19: 1 | DV19: 1 | DW19: 1 | DX19: 1 | DY19: 1 | DZ19: 1 | EA19: 1 | EB19: 1 | EC19: 1 | ED19: 1 | EE19: 1 | EF19: 1 | EG19: 1 | EH19: 1 | EI19: 1 | EJ19: 1 | EK19: 1 | EL19: 1 | EM19: 1 | EN19: 1 | EO19: 1 | EP19: 1 | EQ19: 1 | ER19: 1 | ES19: 1 | ET19: 1 | EU19: 1 | EV19: 1 | EW19: 1 | EX19: 1 | EY19: 1 | EZ19: 1 | FA19: 1 | FB19: 1 | FC19: 1 | FD19: 1 | FE19: 1 | FF19: 1 | FG19: 1 | FH19: 1 | FI19: 1 | FJ19: 1 | FK19: 1 | FL19: 1 | FM19: 1 | FN19: 1 | FO19: 1 | FP19: 1 | FQ19: 1 | FR19: 1 | FS19: 1 | FT19: 1 | FU19: 1 | FV19: 1 | FW19: 1 | FX19: 1 | FY19: 1 | FZ19: 1 | GA19: 1 | GB19: 1 | GC19: 1 | GD19: 1 | GE19: 1 | GF19: 1 | GG19: 1 | GH19: 1
A20: S21 Multimedia | B20: XXX | C20: COCKPIT DOMAIN CONTROLLER - Power 1 | D20: CDC | E20: Cust < 72h | G20: 77 | H20: 0 | I20: =G20+H20 -> 77 | J20: 1 | K20: 1 | L20: 1 | M20: 1 | N20: 1 | O20: 1 | P20: 1 | Q20: 1 | R20: 1 | S20: 1 | T20: 1 | U20: 1 | V20: 1 | W20: 1 | X20: 1 | Y20: 1 | Z20: 1 | AA20: 1 | AB20: 1 | AC20: 1 | AD20: 1 | AE20: 1 | AF20: 1 | AG20: 1 | AH20: 1 | AI20: 1 | AJ20: 1 | AK20: 1 | AL20: 1 | AM20: 1 | AN20: 1 | AO20: 1 | AP20: 1 | AQ20: 1 | AR20: 1 | AS20: 1 | AT20: 1 | AU20: 1 | AV20: 1 | AW20: 1 | AX20: 1 | AY20: 1 | AZ20: 1 | BA20: 1 | BB20: 1 | BC20: 1 | BD20: 1 | BE20: 1 | BF20: 1 | BG20: 1 | BH20: 1 | BI20: 1 | BJ20: 1 | BK20: 1 | BL20: 1 | BM20: 1 | BN20: 1 | BO20: 1 | BP20: 1 | BQ20: 1 | BR20: 1 | BS20: 1 | BT20: 1 | BU20: 1 | BV20: 1 | BW20: 1 | BX20: 1 | BY20: 1 | BZ20: 1 | CA20: 1 | CB20: 1 | CC20: 1 | CD20: 1 | CE20: 1 | CF20: 1 | CG20: 1 | CH20: 1 | CI20: 1 | CJ20: 1 | CK20: 1 | CL20: 1 | CM20: 1 | CN20: 1 | CO20: 1 | CP20: 1 | CQ20: 1 | CR20: 1 | CS20: 1 | CT20: 1 | CU20: 1 | CV20: 1 | CW20: 1 | CX20: 1 | CY20: 1 | CZ20: 1 | DA20: 1 | DB20: 1 | DC20: 1 | DD20: 1 | DE20: 1 | DF20: 1 | DG20: 1 | DH20: 1 | DI20: 1 | DJ20: 1 | DK20: 1 | DL20: 1 | DM20: 1 | DN20: 1 | DO20: 1 | DP20: 1 | DQ20: 1 | DR20: 1 | DS20: 1 | DT20: 1 | DU20: 1 | DV20: 1 | DW20: 1 | DX20: 1 | DY20: 1 | DZ20: 1 | EA20: 1 | EB20: 1 | EC20: 1 | ED20: 1 | EE20: 1 | EF20: 1 | EG20: 1 | EH20: 1 | EI20: 1 | EJ20: 1 | EK20: 1 | EL20: 1 | EM20: 1 | EN20: 1 | EO20: 1 | EP20: 1 | EQ20: 1 | ER20: 1 | ES20: 1 | ET20: 1 | EU20: 1 | EV20: 1 | EW20: 1 | EX20: 1 | EY20: 1 | EZ20: 1 | FA20: 1 | FB20: 1 | FC20: 1 | FD20: 1 | FE20: 1 | FF20: 1 | FG20: 1 | FH20: 1 | FI20: 1 | FJ20: 1 | FK20: 1 | FL20: 1 | FM20: 1 | FN20: 1 | FO20: 1 | FP20: 1 | FQ20: 1 | FR20: 1 | FS20: 1 | FT20: 1 | FU20: 1 | FV20: 1 | FW20: 1 | FX20: 1 | FY20: 1 | FZ20: 1 | GA20: 1 | GB20: 1 | GC20: 1 | GD20: 1 | GE20: 1 | GF20: 1 | GG20: 1 | GH20: 1
A21: S29 Display and Command and Sound | B21: 849 | C21: MULTIFONCTIONNAL ELECTRIC CONTROL | D21: Capacitive Hazard & Doorlock button --> Wake up | E21: Cust : <12h | G21: 78 | H21: 0 | I21: =G21+H21 -> 78 | K21: 1
A22: S48 External lighting and signalling | B22: 1886 | C22: UNDER STEERING WHEEL CONTROLS | D22: CombiSwitch ECU (CSV) to let customer to select wiping speed & light commands | G22: 79 | H22: 0 | I22: =G22+H22 -> 79 | J22: 1 | K22: 1 | L22: 1 | M22: 1 | N22: 1 | O22: 1 | P22: 1 | Q22: 1 | R22: 1 | S22: 1 | T22: 1 | U22: 1 | V22: 1 | W22: 1 | X22: 1 | Y22: 1 | Z22: 1 | AA22: 1 | AB22: 1 | AC22: 1 | AD22: 1 | AE22: 1 | AF22: 1 | AG22: 1 | AH22: 1 | AI22: 1 | AJ22: 1 | AK22: 1 | AL22: 1 | AM22: 1 | AN22: 1 | AO22: 1 | AP22: 1 | AQ22: 1 | AR22: 1 | AS22: 1 | AT22: 1 | AU22: 1 | AV22: 1 | AW22: 1 | AX22: 1 | AY22: 1 | AZ22: 1 | BA22: 1 | BB22: 1 | BC22: 1 | BD22: 1 | BE22: 1 | BF22: 1 | BG22: 1 | BH22: 1 | BI22: 1 | BJ22: 1 | BK22: 1 | BL22: 1 | BM22: 1 | BN22: 1 | BO22: 1 | BP22: 1 | BQ22: 1 | BR22: 1 | BS22: 1 | BT22: 1 | BU22: 1 | BV22: 1 | BW22: 1 | BX22: 1 | BY22: 1 | BZ22: 1 | CA22: 1 | CB22: 1 | CC22: 1 | CD22: 1 | CE22: 1 | CF22: 1 | CG22: 1 | CH22: 1 | CI22: 1 | CJ22: 1 | CK22: 1 | CL22: 1 | CM22: 1 | CN22: 1 | CO22: 1 | CP22: 1 | CQ22: 1 | CR22: 1 | CS22: 1 | CT22: 1 | CU22: 1 | CV22: 1 | CW22: 1 | CX22: 1 | CY22: 1 | CZ22: 1 | DA22: 1 | DB22: 1 | DC22: 1 | DD22: 1 | DE22: 1 | DF22: 1 | DG22: 1 | DH22: 1 | DI22: 1 | DJ22: 1 | DK22: 1 | DL22: 1 | DM22: 1 | DN22: 1 | DO22: 1 | DP22: 1 | DQ22: 1 | DR22: 1 | DS22: 1 | DT22: 1 | DU22: 1 | DV22: 1 | DW22: 1 | DX22: 1 | DY22: 1 | DZ22: 1 | EA22: 1 | EB22: 1 | EC22: 1 | ED22: 1 | EE22: 1 | EF22: 1 | EG22: 1 | EH22: 1 | EI22: 1 | EJ22: 1 | EK22: 1 | EL22: 1 | EM22: 1 | EN22: 1 | EO22: 1 | EP22: 1 | EQ22: 1 | ER22: 1 | ES22: 1 | ET22: 1 | EU22: 1 | EV22: 1 | EW22: 1 | EX22: 1 | EY22: 1 | EZ22: 1 | FA22: 1 | FB22: 1 | FC22: 1 | FD22: 1 | FE22: 1 | FF22: 1 | FG22: 1 | FH22: 1 | FI22: 1 | FJ22: 1 | FK22: 1 | FL22: 1 | FM22: 1 | FN22: 1 | FO22: 1 | FP22: 1 | FQ22: 1 | FR22: 1 | FS22: 1 | FT22: 1 | FU22: 1 | FV22: 1 | FW22: 1 | FX22: 1 | FY22: 1 | FZ22: 1 | GA22: 1 | GB22: 1 | GC22: 1 | GD22: 1 | GE22: 1 | GF22: 1 | GG22: 1 | GH22: 1
A23: S48 External lighting and signalling | B23: XXXX | C23: DASHBOARD EXTERNAL LIGHT CONTROL BUTTONS | D23: Mercedes Like | E23: Cust : <12h | G23: 80 | H23: 0 | I23: =G23+H23 -> 80 | K23: 1
A24: S53 Power Distribution | B24: 225 | C24: DIAGNOSTIC SOCKET | D24: OBD Plug | E24: Factory DM0 | G24: 81 | H24: 0 | I24: =G24+H24 -> 81 | J24: 1 | K24: 1 | L24: 1 | M24: 1 | N24: 1 | O24: 1 | P24: 1 | Q24: 1 | R24: 1 | S24: 1 | T24: 1 | U24: 1 | V24: 1 | W24: 1 | X24: 1 | Y24: 1 | Z24: 1 | AA24: 1 | AB24: 1 | AC24: 1 | AD24: 1 | AE24: 1 | AF24: 1 | AG24: 1 | AH24: 1 | AI24: 1 | AJ24: 1 | AK24: 1 | AL24: 1 | AM24: 1 | AN24: 1 | AO24: 1 | AP24: 1 | AQ24: 1 | AR24: 1 | AS24: 1 | AT24: 1 | AU24: 1 | AV24: 1 | AW24: 1 | AX24: 1 | AY24: 1 | AZ24: 1 | BA24: 1 | BB24: 1 | BC24: 1 | BD24: 1 | BE24: 1 | BF24: 1 | BG24: 1 | BH24: 1 | BI24: 1 | BJ24: 1 | BK24: 1 | BL24: 1 | BM24: 1 | BN24: 1 | BO24: 1 | BP24: 1 | BQ24: 1 | BR24: 1 | BS24: 1 | BT24: 1 | BU24: 1 | BV24: 1 | BW24: 1 | BX24: 1 | BY24: 1 | BZ24: 1 | CA24: 1 | CB24: 1 | CC24: 1 | CD24: 1 | CE24: 1 | CF24: 1 | CG24: 1 | CH24: 1 | CI24: 1 | CJ24: 1 | CK24: 1 | CL24: 1 | CM24: 1 | CN24: 1 | CO24: 1 | CP24: 1 | CQ24: 1 | CR24: 1 | CS24: 1 | CT24: 1 | CU24: 1 | CV24: 1 | CW24: 1 | CX24: 1 | CY24: 1 | CZ24: 1 | DA24: 1 | DB24: 1 | DC24: 1 | DD24: 1 | DE24: 1 | DF24: 1 | DG24: 1 | DH24: 1 | DI24: 1 | DJ24: 1 | DK24: 1 | DL24: 1 | DM24: 1 | DN24: 1 | DO24: 1 | DP24: 1 | DQ24: 1 | DR24: 1 | DS24: 1 | DT24: 1 | DU24: 1 | DV24: 1 | DW24: 1 | DX24: 1 | DY24: 1 | DZ24: 1 | EA24: 1 | EB24: 1 | EC24: 1 | ED24: 1 | EE24: 1 | EF24: 1 | EG24: 1 | EH24: 1 | EI24: 1 | EJ24: 1 | EK24: 1 | EL24: 1 | EM24: 1 | EN24: 1 | EO24: 1 | EP24: 1 | EQ24: 1 | ER24: 1 | ES24: 1 | ET24: 1 | EU24: 1 | EV24: 1 | EW24: 1 | EX24: 1 | EY24: 1 | EZ24: 1 | FA24: 1 | FB24: 1 | FC24: 1 | FD24: 1 | FE24: 1 | FF24: 1 | FG24: 1 | FH24: 1 | FI24: 1 | FJ24: 1 | FK24: 1 | FL24: 1 | FM24: 1 | FN24: 1 | FO24: 1 | FP24: 1 | FQ24: 1 | FR24: 1 | FS24: 1 | FT24: 1 | FU24: 1 | FV24: 1 | FW24: 1 | FX24: 1 | FY24: 1 | FZ24: 1 | GA24: 1 | GB24: 1 | GC24: 1 | GD24: 1 | GE24: 1 | GF24: 1 | GG24: 1 | GH24: 1
A25: S43 Seats and Driving posture | B25: 2567 | C25: LEFT HAND FRONT SEAT MEMORY ECU | D25: Driver Electrical Seat | E25: Cust : <12h | G25: 82 | H25: 0 | I25: =G25+H25 -> 82 | K25: 1
A26: S43 Seats and Driving posture | B26: 2576 | C26: RIGHT HAND FRONT SEAT MEMORY ECU | D26: Passenger Electrical Seat | E26: Cust : <12h | G26: 83 | H26: 0 | I26: =G26+H26 -> 83 | K26: 1
A27: S45 Laterals doors | B27: 3016 | C27: RIGHT SLIDING DOOR | D27: Power Sliding Door (Right Side) | E27: Cust <1h | G27: 84 | H27: 0 | I27: =G27+H27 -> 84 | K27: 1
A28: S45 Laterals doors | B28: 3017 | C28: LEFT SLIDING DOOR | D28: Power Sliding Door (Left Side) | E28: Cust <1h | G28: 85 | H28: 0 | I28: =G28+H28 -> 85 | K28: 1
A29: S46 Back door and Tailgate | B29: 1048 | C29: TAILGATE ECU | D29: Power BackDoor | E29: Cust <1h | G29: 87 | H29: 0 | I29: =G29+H29 -> 87 | K29: 1
B31: 946 | C31: HEVC | D31: HEVC | F31: 0 | G31: 89 | H31: 0 | I31: =G31+H31 -> 89 | J31: 1 | K31: 1 | L31: 1 | M31: 1 | N31: 1 | O31: 1 | P31: 1 | Q31: 1 | R31: 1 | S31: 1 | T31: 1 | U31: 1 | V31: 1 | W31: 1 | X31: 1 | Y31: 1 | Z31: 1 | AA31: 1 | AB31: 1 | AC31: 1 | AD31: 1 | AE31: 1 | AF31: 1 | AG31: 1 | AH31: 1 | AI31: 1 | AJ31: 1 | AK31: 1 | AL31: 1 | AM31: 1 | AN31: 1 | AO31: 1 | AP31: 1 | AQ31: 1 | AR31: 1 | AS31: 1 | AT31: 1 | AU31: 1 | AV31: 1 | AW31: 1 | AX31: 1 | AY31: 1 | AZ31: 1 | BA31: 1 | BB31: 1 | BC31: 1 | BD31: 1 | BE31: 1 | BF31: 1 | BG31: 1 | BH31: 1 | BI31: 1 | BJ31: 1 | BK31: 1 | BL31: 1 | BM31: 1 | BN31: 1 | BO31: 1 | BP31: 1 | BQ31: 1 | BR31: 1 | BS31: 1 | BT31: 1 | BU31: 1 | BV31: 1 | BW31: 1 | BX31: 1 | BY31: 1 | BZ31: 1 | CA31: 1 | CB31: 1 | CC31: 1 | CD31: 1 | CE31: 1 | CF31: 1 | CG31: 1 | CH31: 1 | CI31: 1 | CJ31: 1 | CK31: 1 | CL31: 1 | CM31: 1 | CN31: 1 | CO31: 1 | CP31: 1 | CQ31: 1 | CR31: 1 | CS31: 1 | CT31: 1 | CU31: 1 | CV31: 1 | CW31: 1 | CX31: 1 | CY31: 1 | CZ31: 1 | DA31: 1 | DB31: 1 | DC31: 1 | DD31: 1 | DE31: 1 | DF31: 1 | DG31: 1 | DH31: 1 | DI31: 1 | DJ31: 1 | DK31: 1 | DL31: 1 | DM31: 1 | DN31: 1 | DO31: 1 | DP31: 1 | DQ31: 1 | DR31: 1 | DS31: 1 | DT31: 1 | DU31: 1 | DV31: 1 | DW31: 1 | DX31: 1 | DY31: 1 | DZ31: 1 | EA31: 1 | EB31: 1 | EC31: 1 | ED31: 1 | EE31: 1 | EF31: 1 | EG31: 1 | EH31: 1 | EI31: 1 | EJ31: 1 | EK31: 1 | EL31: 1 | EM31: 1 | EN31: 1 | EO31: 1 | EP31: 1 | EQ31: 1 | ER31: 1 | ES31: 1 | ET31: 1 | EU31: 1 | EV31: 1 | EW31: 1 | EX31: 1 | EY31: 1 | EZ31: 1 | FA31: 1 | FB31: 1 | FC31: 1 | FD31: 1 | FE31: 1 | FF31: 1 | FG31: 1 | FH31: 1 | FI31: 1 | FJ31: 1 | FK31: 1 | FL31: 1 | FM31: 1 | FN31: 1 | FO31: 1 | FP31: 1 | FQ31: 1 | FR31: 1 | FS31: 1 | FT31: 1 | FU31: 1 | FV31: 1 | FW31: 1 | FX31: 1 | FY31: 1 | FZ31: 1 | GA31: 1 | GB31: 1 | GC31: 1 | GD31: 1 | GE31: 1 | GF31: 1 | GG31: 1 | GH31: 1
I32: =G32+H32 -> 0
A33: S28 Access and Vehicle Protection | B33: 2671, 1838,2496,2497 | C33: VOLUMETRIC ALARM ECU | D33: Volumic Alarm | E33: Cust : if 12V Bat OK | G33: 88 | H33: 0 | I33: =G33+H33 -> 88 | K33: 1
A34: S30 Engine Start and Stop | B34: 2918 | C34: ALCOHOL INTERLOCK DEVICE ECU | D34: Ethylotest | E34: Cust : if 12V Bat OK | G34: 90 | H34: 0 | I34: =G34+H34 -> 90 | K34: 1
B35: XXX | C35: CHRONOTACHYGRAPHE | D35: 2.5t or 9 peoples | E35: Cust : if 12V Bat OK | G35: 91 | H35: 0 | I35: =G35+H35 -> 91 | K35: 1
A36: S27 batterie LIB 12V | C36: BMS LIB 12V | D36: BMS LIB 12V | F36: 0.001 | G36: 92 | H36: 0 | I36: =G36+H36 -> 92 | J36: 0 | K36: 1 | L36: 0 | M36: 0 | N36: 0 | O36: 0 | P36: 0 | Q36: 0 | R36: 0 | S36: 0 | T36: 0 | U36: 0 | V36: 0 | W36: 0 | X36: 0 | Y36: 0 | Z36: 0 | AA36: 0 | AB36: 0 | AC36: 0 | AD36: 0 | AE36: 0 | AF36: 0 | AG36: 0 | AH36: 0 | AI36: 0 | AJ36: 0 | AK36: 0 | AL36: 0 | AM36: 0 | AN36: 0 | AO36: 0 | AP36: 0 | AQ36: 0 | AR36: 0 | AS36: 0 | AT36: 0 | AU36: 0 | AV36: 0 | AW36: 0 | AX36: 0 | AY36: 0 | AZ36: 0 | BA36: 0 | BB36: 0 | BC36: 0 | BD36: 0 | BE36: 0 | BF36: 0 | BG36: 0 | BH36: 0 | BI36: 0 | BJ36: 0 | BK36: 0 | BL36: 0 | BM36: 0 | BN36: 0 | BO36: 0 | BP36: 0 | BQ36: 0 | BR36: 0 | BS36: 0 | BT36: 0 | BU36: 0 | BV36: 0 | BW36: 0 | BX36: 0 | BY36: 0 | BZ36: 0 | CA36: 0 | CB36: 0 | CC36: 0 | CD36: 0 | CE36: 0 | CF36: 0 | CG36: 0 | CH36: 0 | CI36: 0 | CJ36: 0 | CK36: 0 | CL36: 0 | CM36: 0 | CN36: 0 | CO36: 0 | CP36: 0 | CQ36: 0 | CR36: 0 | CS36: 0 | CT36: 0 | CU36: 0 | CV36: 0 | CW36: 0 | CX36: 0 | CY36: 0 | CZ36: 0 | DA36: 0 | DB36: 0 | DC36: 0 | DD36: 0 | DE36: 0 | DF36: 0 | DG36: 0 | DH36: 0 | DI36: 0 | DJ36: 0 | DK36: 0 | DL36: 0 | DM36: 0 | DN36: 0 | DO36: 0 | DP36: 0 | DQ36: 0 | DR36: 0 | DS36: 0 | DT36: 0 | DU36: 0 | DV36: 0 | DW36: 0 | DX36: 0 | DY36: 0 | DZ36: 0 | EA36: 0 | EB36: 0 | EC36: 0 | ED36: 0 | EE36: 0 | EF36: 0 | EG36: 0 | EH36: 0 | EI36: 0 | EJ36: 0 | EK36: 0 | EL36: 0 | EM36: 0 | EN36: 0 | EO36: 0 | EP36: 0 | EQ36: 0 | ER36: 0 | ES36: 0 | ET36: 0 | EU36: 0 | EV36: 0 | EW36: 0 | EX36: 0 | EY36: 0 | EZ36: 0 | FA36: 0 | FB36: 0 | FC36: 0 | FD36: 0 | FE36: 0 | FF36: 0 | FG36: 0 | FH36: 0 | FI36: 0 | FJ36: 0 | FK36: 0 | FL36: 0 | FM36: 0 | FN36: 0 | FO36: 0 | FP36: 0 | FQ36: 0 | FR36: 0 | FS36: 0 | FT36: 0 | FU36: 0 | FV36: 0 | FW36: 0 | FX36: 0 | FY36: 0 | FZ36: 0 | GA36: 0 | GB36: 0 | GC36: 0 | GD36: 0 | GE36: 0 | GF36: 0 | GG36: 0 | GH36: 0 | GI36: 0 | GJ36: 0 | GK36: 0 | GL36: 0 | GM36: 0
A37: S28 Access and Vehicle Protection | B37: 2003 | C37: HANDS-FREE ACCESS ECU | D37: HFM transport 10 jours | E37: Cust : if 12V Bat OK | G37: 93 | H37: 0 | I37: =G37+H37 -> 93 | J37: 1 | K37: 1 | L37: 1 | M37: 1 | N37: 1 | O37: 1 | P37: 1 | Q37: 1 | R37: 1 | S37: 1 | T37: 1 | U37: 1 | V37: 1 | W37: 1 | X37: 1 | Y37: 1 | Z37: 1 | AA37: 1 | AB37: 1 | AC37: 1 | AD37: 1
C40: VAN / DELIVERY / CARGO | D40: Dark Current µA | E40: 3secondes | F40: =SUM(F2:F35) -> 0 | G40: =SUMPRODUCT($J2:$J35,G2:G35) -> 1387 | H40: =SUMPRODUCT($J7:$J39,H7:H39) -> 0 | I40: =SUM(I7:I39) -> 2269 | K40: =SUMPRODUCT($I2:$I37,K2:K37) -> 2568 | L40: =SUMPRODUCT($I2:$I35,L2:L35) -> 1387 | M40: =SUMPRODUCT($I2:$I35,M2:M35) -> 1387 | N40: =SUMPRODUCT($I2:$I35,N2:N35) -> 1387 | O40: =SUMPRODUCT($I2:$I35,O2:O35) -> 1387 | P40: =SUMPRODUCT($I2:$I35,P2:P35) -> 1387 | Q40: =SUMPRODUCT($I2:$I35,Q2:Q35) -> 1387 | R40: =SUMPRODUCT($I2:$I35,R2:R35) -> 1387 | S40: =SUMPRODUCT($I2:$I35,S2:S35) -> 1387 | ... GH40: =SUMPRODUCT($I2:$I35,GH2:GH35) -> 1387
D41: Dark Current mA | F41: =F40*1000 -> 0 | G41: =G40/1000 -> 1.387 | H41: =H40/1000 -> 0 | I41: =I40/1000 -> 2.269 | K41: =K40/1000 -> 2.568 | L41: =L40/1000 -> 1.387 | M41: =M40/1000 -> 1.387 | N41: =N40/1000 -> 1.387 | O41: =O40/1000 -> 1.387 | P41: =P40/1000 -> 1.387 | Q41: =Q40/1000 -> 1.387 | R41: =R40/1000 -> 1.387 | ... GH41: =GH40/1000 -> 1.387
D42: 12h Energy mAh | E42: 2 secondes | F42: =(F40-#REF!-#REF!-#REF!) -> #REF! | K42: =K41*12 -> 30.816 | L42: =L41*12 -> 16.644 | M42: =M41*12 -> 16.644 | N42: =N41*12 -> 16.644 | O42: =O41*12 -> 16.644 | P42: =P41*12 -> 16.644 | Q42: =Q41*12 -> 16.644 | R42: =R41*12 -> 16.644 | ... GH42: =GH41*12 -> 16.644
D43: LP Energy mAh | F43: =F42*1000 -> #REF! | K43: =K42+J43 -> 30.816 | L43: =L42+K43 -> 47.46 | M43: =M42+L43 -> 64.104 | N43: =N42+M43 -> 80.748 | O43: =O42+N43 -> 97.392 | P43: =P42+O43 -> 114.036 | Q43: =Q42+P43 -> 130.68 | R43: =R42+Q43 -> 147.324 | ... GH43: =GH42+GG43 -> 3010.092
...

Sheet Logistic Wo unplug
A1: System | B1: Device (LCABLE) | C1: Name (LCABLE) | D1: Free Explanation | E1: Low Power needs | F1: Load Technical Wake up 8h | G1: Load Dark Current | H1: SmartMOS Dark Current | I1: Total Dark Current | J1: 0 | K1: =J1+12 -> 12 | L1: =K1+12 -> 24 | M1: =L1+12 -> 36 | N1: =M1+12 -> 48 | O1: =N1+12 -> 60 | P1: =O1+12 -> 72 | Q1: =P1+12 -> 84 | R1: =Q1+12 -> 96 | ... GH1: =GG1+12 -> 2160
B2: 1094 | C2: VDC | E2: Fusible + Bat | G2: 330 | I2: =G2+H2 -> 330 | J2: 1 | K2: 1 | L2: 1 | M2: 1 | N2: 1 | O2: 1 | P2: 1 | Q2: 1 | R2: 1 | S2: 1 | T2: 1 | U2: 1 | V2: 1 | W2: 1 | X2: 1 | Y2: 1 | Z2: 1 | AA2: 1 | AB2: 1 | AC2: 1 | AD2: 1 | AE2: 1 | AF2: 1 | AG2: 1 | AH2: 1 | AI2: 1 | AJ2: 1 | AK2: 1 | AL2: 1 | AM2: 1 | AN2: 1 | AO2: 1 | AP2: 1 | AQ2: 1 | AR2: 1 | AS2: 1 | AT2: 1 | AU2: 1 | AV2: 1 | AW2: 1 | AX2: 1 | AY2: 1 | AZ2: 1 | BA2: 1 | BB2: 1 | BC2: 1 | BD2: 1 | BE2: 1 | BF2: 1 | BG2: 1 | BH2: 1 | BI2: 1 | BJ2: 1 | BK2: 1 | BL2: 1 | BM2: 1 | BN2: 1 | BO2: 1 | BP2: 1 | BQ2: 1 | BR2: 1 | BS2: 1 | BT2: 1 | BU2: 1 | BV2: 1 | BW2: 1 | BX2: 1 | BY2: 1 | BZ2: 1 | CA2: 1 | CB2: 1 | CC2: 1 | CD2: 1 | CE2: 1 | CF2: 1 | CG2: 1 | CH2: 1 | CI2: 1 | CJ2: 1 | CK2: 1 | CL2: 1 | CM2: 1 | CN2: 1 | CO2: 1 | CP2: 1 | CQ2: 1 | CR2: 1 | CS2: 1 | CT2: 1 | CU2: 1 | CV2: 1 | CW2: 1 | CX2: 1 | CY2: 1 | CZ2: 1 | DA2: 1 | DB2: 1 | DC2: 1 | DD2: 1 | DE2: 1 | DF2: 1 | DG2: 1 | DH2: 1 | DI2: 1 | DJ2: 1 | DK2: 1 | DL2: 1 | DM2: 1 | DN2: 1 | DO2: 1 | DP2: 1 | DQ2: 1 | DR2: 1 | DS2: 1 | DT2: 1 | DU2: 1 | DV2: 1 | DW2: 1 | DX2: 1 | DY2: 1 | DZ2: 1 | EA2: 1 | EB2: 1 | EC2: 1 | ED2: 1 | EE2: 1 | EF2: 1 | EG2: 1 | EH2: 1 | EI2: 1 | EJ2: 1 | EK2: 1 | EL2: 1 | EM2: 1 | EN2: 1 | EO2: 1 | EP2: 1 | EQ2: 1 | ER2: 1 | ES2: 1 | ET2: 1 | EU2: 1 | EV2: 1 | EW2: 1 | EX2: 1 | EY2: 1 | EZ2: 1 | FA2: 1 | FB2: 1 | FC2: 1 | FD2: 1 | FE2: 1 | FF2: 1 | FG2: 1 | FH2: 1 | FI2: 1 | FJ2: 1 | FK2: 1 | FL2: 1 | FM2: 1 | FN2: 1 | FO2: 1 | FP2: 1 | FQ2: 1 | FR2: 1 | FS2: 1 | FT2: 1 | FU2: 1 | FV2: 1 | FW2: 1 | FX2: 1 | FY2: 1 | FZ2: 1 | GA2: 1 | GB2: 1 | GC2: 1 | GD2: 1 | GE2: 1 | GF2: 1 | GG2: 1 | GH2: 1
B3: 1232 | C3: EPS | E3: Fusible + Bat | G3: 71 | I3: =G3+H3 -> 71 | J3: 1 | K3: 1 | L3: 1 | M3: 1 | N3: 1 | O3: 1 | P3: 1 | Q3: 1 | R3: 1 | S3: 1 | T3: 1 | U3: 1 | V3: 1 | W3: 1 | X3: 1 | Y3: 1 | Z3: 1 | AA3: 1 | AB3: 1 | AC3: 1 | AD3: 1 | AE3: 1 | AF3: 1 | AG3: 1 | AH3: 1 | AI3: 1 | AJ3: 1 | AK3: 1 | AL3: 1 | AM3: 1 | AN3: 1 | AO3: 1 | AP3: 1 | AQ3: 1 | AR3: 1 | AS3: 1 | AT3: 1 | AU3: 1 | AV3: 1 | AW3: 1 | AX3: 1 | AY3: 1 | AZ3: 1 | BA3: 1 | BB3: 1 | BC3: 1 | BD3: 1 | BE3: 1 | BF3: 1 | BG3: 1 | BH3: 1 | BI3: 1 | BJ3: 1 | BK3: 1 | BL3: 1 | BM3: 1 | BN3: 1 | BO3: 1 | BP3: 1 | BQ3: 1 | BR3: 1 | BS3: 1 | BT3: 1 | BU3: 1 | BV3: 1 | BW3: 1 | BX3: 1 | BY3: 1 | BZ3: 1 | CA3: 1 | CB3: 1 | CC3: 1 | CD3: 1 | CE3: 1 | CF3: 1 | CG3: 1 | CH3: 1 | CI3: 1 | CJ3: 1 | CK3: 1 | CL3: 1 | CM3: 1 | CN3: 1 | CO3: 1 | CP3: 1 | CQ3: 1 | CR3: 1 | CS3: 1 | CT3: 1 | CU3: 1 | CV3: 1 | CW3: 1 | CX3: 1 | CY3: 1 | CZ3: 1 | DA3: 1 | DB3: 1 | DC3: 1 | DD3: 1 | DE3: 1 | DF3: 1 | DG3: 1 | DH3: 1 | DI3: 1 | DJ3: 1 | DK3: 1 | DL3: 1 | DM3: 1 | DN3: 1 | DO3: 1 | DP3: 1 | DQ3: 1 | DR3: 1 | DS3: 1 | DT3: 1 | DU3: 1 | DV3: 1 | DW3: 1 | DX3: 1 | DY3: 1 | DZ3: 1 | EA3: 1 | EB3: 1 | EC3: 1 | ED3: 1 | EE3: 1 | EF3: 1 | EG3: 1 | EH3: 1 | EI3: 1 | EJ3: 1 | EK3: 1 | EL3: 1 | EM3: 1 | EN3: 1 | EO3: 1 | EP3: 1 | EQ3: 1 | ER3: 1 | ES3: 1 | ET3: 1 | EU3: 1 | EV3: 1 | EW3: 1 | EX3: 1 | EY3: 1 | EZ3: 1 | FA3: 1 | FB3: 1 | FC3: 1 | FD3: 1 | FE3: 1 | FF3: 1 | FG3: 1 | FH3: 1 | FI3: 1 | FJ3: 1 | FK3: 1 | FL3: 1 | FM3: 1 | FN3: 1 | FO3: 1 | FP3: 1 | FQ3: 1 | FR3: 1 | FS3: 1 | FT3: 1 | FU3: 1 | FV3: 1 | FW3: 1 | FX3: 1 | FY3: 1 | FZ3: 1 | GA3: 1 | GB3: 1 | GC3: 1 | GD3: 1 | GE3: 1 | GF3: 1 | GG3: 1 | GH3: 1
