Workbook
Name \0: #REF!
Name \a: #REF!
Name \m: #REF!
Name \q: #REF!
Name ____L84: [0]!____L84
Name ___L84: [0]!___L84
Name __L84: [0]!__L84
Name _005明細事業部: #REF!
Name _012事業部明細: #REF!
Name _101事業部明細: #REF!
Name _19565: #REF!
Name _IND84: #REF!
Name _IND91: #REF!
Name _L84: [0]!_L84
Name _M13: #REF!
Name _M14: #REF!
Name _M16: #REF!
Name _M3: #REF!
Name _M4: #REF!
Name _M8: #REF!
Name _MS15: #REF!
Name _R7: #REF!
Name ○と×: #REF!
Name A1A: #REF!
Name aaa: #REF!
Name Abattant: #REF!
Name AccessButton: "PostK9b1_Synthèse_composants_Liste"
Name aci: #REF!
Name AcPilote_i: #REF!
Name afficherMasquerLesFeuilles: [0]!afficherMasquerLesFeuilles
Name Airbags_AR: #REF!
Name Airbags_AV: #REF!
Name AK: [0]!AK
Name alpha1_B: #REF!
Name alpha1_H: #REF!
Name alpha2: #REF!
Name Antennes: #REF!
Name Anti_brouillards: #REF!
Name Attelage: #REF!
Name Avertisseur_sonore: #REF!
Name B_: #REF!
Name BASE: #REF!
Name bdd: #REF!
Name BILAN: #REF!
Name BILAN2: #REF!
Name boitprogrsa: #REF!
Name BOM: #REF!
Name Bouclier_AR: #REF!
Name Bouclier_AV: #REF!
Name Bouclier_AV_R_Type_Aventure: #REF!
Name BoutAbt: #N/A
Name BoutChk: #N/A
Name BoutCns: #N/A
Name BoutPdtdat: #N/A
Name bprsa: #REF!
Name BtnAideLiaison_QuandClic: #REF!
Name BtnAideNomFiche_QuandClic: #REF!
Name BtnAjout_Fiche_techno_QuandClic: #REF!
Name BtnOptions_QuandClic: #REF!
Name BtnPIN_QuandClic: #REF!

Sheet Update
C1: Project name:
C2: Powertrain:
C3: EE Architech:
C4: Application zone:
B6: Sl.No | C6: Date | D6: Update Information | E6: Milestone | F6: Person name
B7: 1 | C7: 43749 | D7: initialisation mise a jour des Profils et des taux d'usage | F7: B. Chiovetta
C9: 45663 | D9: Mise a jour profil conso blower + sièges chauffants + volant chuaffants | F9: P,Daugeron

Sheet Définition

Sheet Bilan DCDC
H1: DC - DC Sizing Charge balance tool
B2: Project name: | E2: Milestone
B3: Powertrain: | E3: Date:
B4: EE Architech: | E4: Pilot wattman:
B5: Application zone:
H6: Electrical load usage rate (in %) for 30mints drive | Z6: Commentaire
B7: List of equipements | E7: Variants | G7: Conso Elec (A) | H7: Profile : Winter <-5°C | M7: Conso Instantatnée MAX | N7: Profile : Mid-season 5°C<15°C | S7: Conso Instantatnée MAX | T7: Profile :Summer T>15°C | Y7: Conso Instantatnée MAX
E8: Base Mettre 1 ou 0 | F8: Upper Mettre 1 ou 0 | H8: 0 - 5mints | I8: 5 - 10mints | J8: 10 - 15mints | K8: 15 - 25mints | L8: 25 - 30mints | N8: 0 - 5mints | O8: 5 - 10mints | P8: 10 - 15mints | Q8: 15 - 25mints | R8: 25 - 30mints | T8: 0 - 5mints | U8: 5 - 10mints | V8: 10 - 15mints | W8: 15 - 25mints | X8: 25 - 30mints
B9: ECLAIRAGES
B10: FEUX DE POSITION AV | H10: 1 | I10: 1 | J10: 1 | K10: 1 | L10: 1 | M10: 1 | N10: 1 | O10: 1 | P10: 1 | Q10: 1 | R10: 1 | S10: 1 | T10: 0 | U10: 0 | V10: 0 | W10: 0 | X10: 0 | Y10: 0
B11: FEUX DE POSITION AR ET DE PLAQUE / POSITION AND PLATE LAMPS | H11: =H10 -> 1 | I11: =I10 -> 1 | J11: =J10 -> 1 | K11: =K10 -> 1 | L11: =L10 -> 1 | M11: 1 | N11: =N10 -> 1 | O11: =O10 -> 1 | P11: =P10 -> 1 | Q11: =Q10 -> 1 | R11: =R10 -> 1 | S11: 1 | T11: =T10 -> 0 | U11: =U10 -> 0 | V11: =V10 -> 0 | W11: =W10 -> 0 | X11: =X10 -> 0 | Y11: 0
B12: ECLAIRAGE TABLEAU DE BORD SXS EV / LIGHTS INSTRUMENT PANEL | H12: =H10 -> 1 | I12: =I10 -> 1 | J12: =J10 -> 1 | K12: =K10 -> 1 | L12: =L10 -> 1 | M12: 1 | N12: =N10 -> 1 | O12: =O10 -> 1 | P12: =P10 -> 1 | Q12: =Q10 -> 1 | R12: =R10 -> 1 | S12: 1 | T12: =T10 -> 0 | U12: =U10 -> 0 | V12: =V10 -> 0 | W12: =W10 -> 0 | X12: =X10 -> 0 | Y12: 0
B13: INTERRUPTEURS VOYANTS DE NUIT / NIGHT LEDS SWITCHES | H13: =H10 -> 1 | I13: =I10 -> 1 | J13: =J10 -> 1 | K13: =K10 -> 1 | L13: =L10 -> 1 | M13: 1 | N13: =N10 -> 1 | O13: =O10 -> 1 | P13: =P10 -> 1 | Q13: =Q10 -> 1 | R13: =R10 -> 1 | S13: 1 | T13: 1 | U13: 1 | V13: 1 | W13: 1 | X13: 1 | Y13: 1
B14: DRL | H14: 0 | I14: 0 | J14: 0 | K14: 0 | L14: 0 | M14: 0 | N14: 0 | O14: 0 | P14: 0 | Q14: 0 | R14: 0 | S14: 0 | T14: 1 | U14: 1 | V14: 1 | W14: 1 | X14: 1 | Y14: 1
B15: LOGO + CROSSING LIGHTING | H15: =H12 -> 1 | I15: =I12 -> 1 | J15: =J12 -> 1 | K15: =K12 -> 1 | L15: =L12 -> 1 | M15: 1 | N15: =N12 -> 1 | O15: =O12 -> 1 | P15: =P12 -> 1 | Q15: =Q12 -> 1 | R15: =R12 -> 1 | S15: 1 | T15: 1 | U15: 1 | V15: 1 | W15: 1 | X15: 1 | Y15: 1
B16: FEUX DE BROUILLARD AVANT (x2) / FRONT FOG LIGHTS (x2) | H16: 1 | I16: 1 | J16: 1 | K16: 1 | L16: 1 | M16: 1 | N16: 1 | O16: 1 | P16: 1 | Q16: 1 | R16: 1 | S16: 1 | T16: 0 | U16: 0 | V16: 0 | W16: 0 | X16: 0 | Y16: 0
B17: FEUX DE BROUILLARD ARRIERE Edg / REAR FOG LAMPS Edg | H17: 1 | I17: 1 | J17: 1 | K17: 1 | L17: 1 | M17: 1 | N17: 1 | O17: 1 | P17: 1 | Q17: 1 | R17: 1 | S17: 1 | T17: 0 | U17: 0 | V17: 0 | W17: 0 | X17: 0 | Y17: 0
B18: FEUX DE BROUILLARD ARRIERE Hdg / REAR FOG LAMPS Hdg | H18: 1 | I18: 1 | J18: 1 | K18: 1 | L18: 1 | M18: 1 | N18: 1 | O18: 1 | P18: 1 | Q18: 1 | R18: 1 | S18: 1 | T18: 0 | U18: 0 | V18: 0 | W18: 0 | X18: 0 | Y18: 0
B19: FEUX INDICATEURS DE DIRECTION / DIRECTION Indication lamp | H19: 0.25 | I19: 0.25 | J19: 0.25 | K19: 0.25 | L19: 0.25 | M19: 0 | N19: 0.25 | O19: 0.25 | P19: 0.25 | Q19: 0.25 | R19: 0.25 | S19: 0 | T19: 0.25 | U19: 0.25 | V19: 0.25 | W19: 0.25 | X19: 0.25 | Y19: 0.5
B20: FEUX DE STOP - Edg / STOP lamp Edg | H20: 0.3 | I20: 0.3 | J20: 0.3 | K20: 0.3 | L20: 0.3 | M20: 1 | N20: 0.3 | O20: 0.3 | P20: 0.3 | Q20: 0.3 | R20: 0.3 | S20: 1 | T20: 0.1 | U20: 0.1 | V20: 0.1 | W20: 0.1 | X20: 0.1 | Y20: 1
B21: FEUX DE STOP - Hdg / STOP lamp Hdg | H21: 0.3 | I21: 0.3 | J21: 0.3 | K21: 0.3 | L21: 0.3 | M21: 1 | N21: 0.3 | O21: 0.3 | P21: 0.3 | Q21: 0.3 | R21: 0.3 | S21: 1 | T21: 0.1 | U21: 0.1 | V21: 0.1 | W21: 0.1 | X21: 0.1 | Y21: 1
B22: FEUX DE CROISEMENT Edg / Low beam lamp | H22: 1 | I22: 1 | J22: 1 | K22: 1 | L22: 1 | M22: 1 | N22: 1 | O22: 1 | P22: 1 | Q22: 1 | R22: 1 | S22: 1 | T22: 0 | U22: 0 | V22: 0 | W22: 0 | X22: 0 | Y22: 0
B23: FEUX DE CROISEMENT Hdg / Low beam lamp | H23: 1 | I23: 1 | J23: 1 | K23: 1 | L23: 1 | M23: 1 | N23: 1 | O23: 1 | P23: 1 | Q23: 1 | R23: 1 | S23: 1 | T23: 0 | U23: 0 | V23: 0 | W23: 0 | X23: 0 | Y23: 0
B24: FEUX DE ROUTE Edg / High beam lamp | H24: 1 | I24: 1 | J24: 1 | K24: 1 | L24: 1 | M24: 1 | N24: 1 | O24: 1 | P24: 1 | Q24: 1 | R24: 1 | S24: 1 | T24: 0 | U24: 0 | V24: 0 | W24: 0 | X24: 0 | Y24: 0
B25: FEUX DE ROUTE Hdg / High beam lamp | H25: 1 | I25: 1 | J25: 1 | K25: 1 | L25: 1 | M25: 1 | N25: 1 | O25: 1 | P25: 1 | Q25: 1 | R25: 1 | S25: 1 | T25: 0 | U25: 0 | V25: 0 | W25: 0 | X25: 0 | Y25: 0
B26: VISIBILITE
B27: LUNETTE DEGIVRANTE / Rear Defroster | H27: 1 | I27: 0.95 | J27: 0.95 | K27: 0 | L27: 0 | M27: 1 | N27: 1 | O27: 0.5 | P27: 0 | Q27: 0 | R27: 0 | S27: 1 | T27: 0.8 | U27: 0 | V27: 0 | W27: 0 | X27: 0 | Y27: 0
B28: RETROVISEUR DEGIVRANT (x2) / Heated Mirror Defroster | H28: 1 | I28: 0.95 | J28: 0.95 | K28: 0 | L28: 0 | M28: 1 | N28: 1 | O28: 0.5 | P28: 0 | Q28: 0 | R28: 0 | S28: 1 | T28: 0.8 | U28: 0 | V28: 0 | W28: 0 | X28: 0 | Y28: 0
B29: PAREBRISE CHAUFFANT / Heated windscreen | H29: 1 | I29: 0.95 | J29: 0 | K29: 0 | L29: 0 | M29: 1 | N29: 1 | O29: 0 | P29: 0 | Q29: 0 | R29: 0 | S29: 1 | T29: 0.15 | U29: 0 | V29: 0 | W29: 0 | X29: 0 | Y29: 0
B30: ESSUIE VITRE AVANT / FRONT WINDOW WIPER No activated if Heated windscreen is ON | H30: 1 | I30: 1 | J30: 1 | K30: 1 | L30: 1 | M30: 0 | N30: 1 | O30: 1 | P30: 1 | Q30: 1 | R30: 1 | S30: 0 | T30: 1 | U30: 1 | V30: 1 | W30: 1 | X30: 1 | Y30: 0
B31: ESSUIE VITRE ARRIERE / REAR WINDOW WIPER | H31: 0 | I31: 0 | J31: 0 | K31: 0 | L31: 0 | M31: 0 | N31: 0 | O31: 0 | P31: 0 | Q31: 0 | R31: 0 | S31: 0 | T31: 0 | U31: 0 | V31: 0 | W31: 0 | X31: 0 | Y31: 0
B32: CONFORT COCKPIT
B33: GMV (HVAC) HABITACLE _HOT MODE | H33: 1 | I33: 0.75 | J33: 0.55 | K33: 0.45 | L33: 0.4 | M33: 1 | N33: 1 | O33: 0.75 | P33: 0.55 | Q33: 0.45 | R33: 0.4 | S33: 1 | T33: 0 | U33: 0 | V33: 0 | W33: 0 | X33: 0 | Y33: 0
B34: GMV (HVAC) HABITACLE _COLD MODE | H34: 0 | I34: 0 | J34: 0 | K34: 0 | L34: 0 | M34: 0 | N34: 0 | O34: 0 | P34: 0 | Q34: 0 | R34: 0 | S34: 0 | T34: 1 | U34: 0.75 | V34: 0.6 | W34: 0.55 | X34: 0.5 | Y34: 1
B35: COMPRESSEUR CA HV | H35: 0 | I35: 0 | J35: 0 | K35: 0 | L35: 0 | M35: 0 | N35: 0.5 | O35: 0.5 | P35: 0.5 | Q35: 0.5 | R35: 0.5 | S35: 0 | T35: 1 | U35: 1 | V35: 1 | W35: 1 | X35: 1 | Y35: 1
B36: SIEGES CHAUFFANTS AVANTS | H36: 1 | I36: 1 | J36: 1 | K36: 0.63 | L36: 0.63 | M36: 1 | N36: 1 | O36: 0.8 | P36: 0.7 | Q36: 0 | R36: 0 | S36: 1 | T36: 0 | U36: 0 | V36: 0 | W36: 0 | X36: 0 | Y36: 0
B37: SIEGES CHAUFFANTS ARRIERES | H37: 1 | I37: 1 | J37: 1 | K37: 0.63 | L37: 0.63 | M37: 1 | N37: 1 | O37: 1 | P37: 1 | Q37: 0 | R37: 0 | S37: 1 | T37: 0 | U37: 0 | V37: 0 | W37: 0 | X37: 0 | Y37: 0
B38: Volant chauffant | H38: 1 | I38: 1 | J38: 0.63 | K38: 0.63 | L38: 0.63 | M38: 1 | N38: 1 | O38: 1 | P38: 0 | Q38: 0 | R38: 0 | S38: 1 | T38: 0 | U38: 0 | V38: 0 | W38: 0 | X38: 0 | Y38: 0
B39: CTP sur 12V | H39: 0.8 | I39: 0.8 | J39: 0.8 | K39: 0.5 | L39: 0.5 | M39: 0.8 | N39: 0.8 | O39: 0.4 | P39: 0 | Q39: 0 | R39: 0 | S39: 0.8 | T39: 0 | U39: 0 | V39: 0 | W39: 0 | X39: 0 | Y39: 0
B40: EV ELECTROVANNE | H40: 0.3 | I40: 0.3 | J40: 0.5 | K40: 0.5 | L40: 0.5 | M40: 1 | N40: 0.3 | O40: 0.5 | P40: 0.6 | Q40: 0.6 | R40: 0.6 | S40: 1 | T40: 0.7 | U40: 0.8 | V40: 1 | W40: 1 | X40: 1 | Y40: 1
...

Sheet Graph
A2: Winter <-5°C | F2: Mid-season 5°C<T<15 | K2: Summer T>15°C
A3: Time (Mint) | B3: Base Vehicle global conso (A) | C3: Upper Vehicle global conso (A) | D3: DCDC output | F3: Time (Mint) | G3: Base Vehicle global conso (A) | H3: Upper Vehicle global conso (A) | I3: DCDC output | K3: Time (Mint) | L3: Base Vehicle global conso (A) | M3: Upper Vehicle global conso (A) | N3: DCDC output
A4: 0 | B4: ='Bilan DCDC'!H93 -> 0 | C4: ='Bilan DCDC'!H92 -> 0 | D4: ='Bilan DCDC'!C90 -> 250 | F4: 0 | G4: ='Bilan DCDC'!M93 -> 0 | H4: =+'Bilan DCDC'!N92 -> 0 | I4: ='Bilan DCDC'!C91 -> 250 | K4: 0 | L4: ='Bilan DCDC'!T93 -> 0 | M4: ='Bilan DCDC'!T92 -> 0 | N4: ='Bilan DCDC'!C91 -> 250
A5: 5 | B5: =B4 -> 0 | C5: =C4 -> 0 | D5: =D4 -> 250 | F5: 5 | G5: =G4 -> 0 | H5: =H4 -> 0 | I5: =I4 -> 250 | K5: 5 | L5: =L4 -> 0 | M5: =M4 -> 0 | N5: =N4 -> 250
A6: 5 | B6: ='Bilan DCDC'!I93 -> 0 | C6: ='Bilan DCDC'!I92 -> 0 | D6: =D4 -> 250 | F6: 5 | G6: ='Bilan DCDC'!O93 -> 0 | H6: ='Bilan DCDC'!O92 -> 0 | I6: =I4 -> 250 | K6: 5 | L6: ='Bilan DCDC'!U93 -> 0 | M6: ='Bilan DCDC'!U92 -> 0 | N6: =N4 -> 250
A7: 10 | B7: =B6 -> 0 | C7: =C6 -> 0 | D7: =D5 -> 250 | F7: 10 | G7: =G6 -> 0 | H7: =H6 -> 0 | I7: =I5 -> 250 | K7: 10 | L7: =L6 -> 0 | M7: =M6 -> 0 | N7: =N5 -> 250
A8: 10 | B8: ='Bilan DCDC'!J93 -> 0 | C8: ='Bilan DCDC'!J92 -> 0 | D8: =D4 -> 250 | F8: 10 | G8: ='Bilan DCDC'!P93 -> 0 | H8: ='Bilan DCDC'!P92 -> 0 | I8: =I4 -> 250 | K8: 10 | L8: ='Bilan DCDC'!V93 -> 0 | M8: ='Bilan DCDC'!V92 -> 0 | N8: =N4 -> 250
A9: 15 | B9: =B8 -> 0 | C9: =C8 -> 0 | D9: =D4 -> 250 | F9: 15 | G9: =G8 -> 0 | H9: =H8 -> 0 | I9: =I4 -> 250 | K9: 15 | L9: =L8 -> 0 | M9: =M8 -> 0 | N9: =N4 -> 250
A10: 15 | B10: ='Bilan DCDC'!K93 -> 0 | C10: ='Bilan DCDC'!K92 -> 0 | D10: =D4 -> 250 | F10: 15 | G10: ='Bilan DCDC'!Q93 -> 0 | H10: ='Bilan DCDC'!Q92 -> 0 | I10: =I4 -> 250 | K10: 15 | L10: ='Bilan DCDC'!W93 -> 0 | M10: ='Bilan DCDC'!W92 -> 0 | N10: =N4 -> 250
A11: 15 | B11: =B10 -> 0 | C11: =C10 -> 0 | D11: =D7 -> 250 | F11: 15 | G11: =G10 -> 0 | H11: =H10 -> 0 | I11: =I7 -> 250 | K11: 15 | L11: =L10 -> 0 | M11: =M10 -> 0 | N11: =N7 -> 250
A12: 25 | B12: =B11 -> 0 | C12: =C11 -> 0 | D12: =D7 -> 250 | F12: 25 | G12: =G11 -> 0 | H12: =H11 -> 0 | I12: =I7 -> 250 | K12: 25 | L12: =L11 -> 0 | M12: =M11 -> 0 | N12: =N7 -> 250
A13: 25 | B13: ='Bilan DCDC'!L93 -> 0 | C13: ='Bilan DCDC'!L92 -> 0 | D13: =D7 -> 250 | F13: 25 | G13: ='Bilan DCDC'!R93 -> 0 | H13: ='Bilan DCDC'!R92 -> 0 | I13: =I7 -> 250 | K13: 25 | L13: ='Bilan DCDC'!X93 -> 0 | M13: ='Bilan DCDC'!X92 -> 0 | N13: =N7 -> 250
A14: 25 | B14: =B13 -> 0 | C14: =C13 -> 0 | D14: =D4 -> 250 | F14: 25 | G14: =G13 -> 0 | H14: =H13 -> 0 | I14: =I4 -> 250 | K14: 25 | L14: =L13 -> 0 | M14: =M13 -> 0 | N14: =N4 -> 250
A15: 30 | B15: =B14 -> 0 | C15: =C14 -> 0 | D15: =D4 -> 250 | F15: 30 | G15: =G14 -> 0 | H15: =H14 -> 0 | I15: =I4 -> 250 | K15: 30 | L15: =L14 -> 0 | M15: =M14 -> 0 | N15: =N4 -> 250

Sheet Bilan -7°C
C2: ELECTRIQUE | J2: WLTC - 7°C tool
B3: Project name: | I3: =23*0.8 -> 18.4
B4: Date:
B5: Pilot wattman: | I5: =218/13 -> 16.769231
B7: WLTC - 7°C Prognosis (W) | E7: Cycle 1 | F7: Cycle 2 | G7: Cycle 3 | I7: =17/13 -> 1.3076923
B8: =E13 -> Version vh 1 | D8: =E14 -> Base | E8: =J122 -> 0 | F8: =R122 -> 0 | G8: =Y122 -> 0
B9: =E13 -> Version vh 1 | D9: =F14 -> Upper | E9: =J119 -> 0 | F9: =R119 -> 0 | G9: =Y119 -> 0 | I9: =I10*13.5 -> 37.26
B10: =G13 -> Version vh 2 | D10: =G14 -> Base | E10: =J128 -> 0 | F10: =R128 -> 0 | G10: =Y128 -> 0 | I10: =23*0.12 -> 2.76
B11: =G13 -> Version vh 2 | D11: =H14 -> Upper | E11: =J125 -> 0 | F11: =R125 -> 0 | G11: =Y125 -> 0
B13: List of equipements | E13: Version vh 1 | G13: Version vh 2 | I13: Conso Elec (A) | J13: Cycle 1 | R13: Cycle 2 | Y13: Cycle 3 | AE13: Conso Instantatnée MAX | AF13: Commentaire
E14: Base | F14: Upper | G14: Base | H14: Upper | J14: 0 - 1,67mints | K14: 1,68 - 4mints | L14: 4 - 7mints | M14: 7 - 8,16mints | N14: 8,16 - 12,25mints | O14: 12.25 - 25mints | P14: 25 - 30mints | R14: 0 - 5mints | S14: 5 - 7mints | T14: 7 - 8,16mints | U14: 8,16 - 15mints | V14: 15 - 25mints | W14: 25 - 30mints | Y14: 0 - 5mints | Z14: 5 - 7mints | AA14: 7 - 8,16mints | AB14: 8,16 - 15mints | AC14: 15 - 25mints | AD14: 25 - 30mints
B15: ECLAIRAGES
B16: FEUX DE POSITION AV | I16: 0 | J16: 1 | K16: 1 | L16: 1 | M16: 1 | N16: 1 | O16: 1 | P16: 1 | R16: 1 | S16: 1 | T16: 1 | U16: 1 | V16: 1 | W16: 1 | X16: 1 | Y16: 1 | Z16: 1 | AA16: 1 | AB16: 1 | AC16: 1 | AD16: 1 | AE16: 0
B17: FEUX DE POSITION AR ET DE PLAQUE / POSITION AND PLATE LAMPS | I17: 0 | J17: 1 | K17: 1 | L17: 1 | M17: 1 | N17: 1 | O17: 1 | P17: 1 | R17: 1 | S17: 1 | T17: 1 | U17: 1 | V17: 1 | W17: 1 | X17: 1 | Y17: 1 | Z17: 1 | AA17: 1 | AB17: 1 | AC17: 1 | AD17: 1 | AE17: 0
B18: ECLAIRAGE TABLEAU DE BORD SXS EV / LIGHTS INSTRUMENT PANEL | I18: 0 | J18: 1 | K18: 1 | L18: 1 | M18: 1 | N18: 1 | O18: 1 | P18: 1 | R18: 1 | S18: 1 | T18: 1 | U18: 1 | V18: 1 | W18: 1 | X18: 1 | Y18: 1 | Z18: 1 | AA18: 1 | AB18: 1 | AC18: 1 | AD18: 1 | AE18: 0.1
B19: INTERRUPTEURS VOYANTS DE NUIT / NIGHT LEDS SWITCHES | I19: 0 | J19: 1 | K19: 1 | L19: 1 | M19: 1 | N19: 1 | O19: 1 | P19: 1 | R19: 1 | S19: 1 | T19: 1 | U19: 1 | V19: 1 | W19: 1 | X19: 1 | Y19: 1 | Z19: 1 | AA19: 1 | AB19: 1 | AC19: 1 | AD19: 1 | AE19: 0.1
B20: DRL | I20: 0 | J20: 0 | K20: 0 | L20: 0 | M20: 0 | N20: 0 | O20: 0 | P20: 0 | R20: 0 | S20: 0 | T20: 0 | U20: 0 | V20: 0 | W20: 0 | Y20: 0 | Z20: 0 | AA20: 0 | AB20: 0 | AC20: 0 | AD20: 0 | AE20: 0
B21: LOGO + CROSSING LIGHTING | I21: 0 | J21: 1 | K21: 1 | L21: 1 | M21: 1 | N21: 1 | O21: 1 | P21: 1 | R21: 1 | S21: 1 | T21: 1 | U21: 1 | V21: 1 | W21: 1 | X21: 0.3 | Y21: 1 | Z21: 1 | AA21: 1 | AB21: 1 | AC21: 1 | AD21: 1 | AE21: 0.1
B22: FEUX DE BROUILLARD AVANT (x2) / FRONT FOG LIGHTS (x2) | I22: 0 | J22: 0 | K22: 0 | L22: 0 | M22: 0 | N22: 0 | O22: 0 | P22: 0 | R22: 0 | S22: 0 | T22: 0 | U22: 0 | V22: 0 | W22: 0 | Y22: 0 | Z22: 0 | AA22: 0 | AB22: 0 | AC22: 0 | AD22: 0 | AE22: 0.1
B23: FEUX DE BROUILLARD ARRIERE Edg / REAR FOG LAMPS Edg | I23: 0 | J23: 0 | K23: 0 | L23: 0 | M23: 0 | N23: 0 | O23: 0 | P23: 0 | R23: 0 | S23: 0 | T23: 0 | U23: 0 | V23: 0 | W23: 0 | Y23: 0 | Z23: 0 | AA23: 0 | AB23: 0 | AC23: 0 | AD23: 0
B24: FEUX DE BROUILLARD ARRIERE Hdg / REAR FOG LAMPS Hdg | I24: 0 | J24: 0 | K24: 0 | L24: 0 | M24: 0 | N24: 0 | O24: 0 | P24: 0 | R24: 0 | S24: 0 | T24: 0 | U24: 0 | V24: 0 | W24: 0 | Y24: 0 | Z24: 0 | AA24: 0 | AB24: 0 | AC24: 0 | AD24: 0
B25: FEUX INDICATEURS DE DIRECTION / DIRECTION Indication lamp | I25: 0 | J25: 0 | K25: 0 | L25: 0 | M25: 0 | N25: 0 | O25: 0 | P25: 0 | R25: 0 | S25: 0 | T25: 0 | U25: 0 | V25: 0 | W25: 0 | Y25: 0 | Z25: 0 | AA25: 0 | AB25: 0 | AC25: 0 | AD25: 0
B26: FEUX DE STOP - Edg / STOP lamp Edg | I26: 0 | J26: 1 | K26: 1 | L26: 1 | M26: 0 | N26: 0 | O26: 0 | P26: 0 | R26: 1 | S26: 1 | T26: 0 | U26: 0 | V26: 0 | W26: 0 | Y26: 1 | Z26: 1 | AA26: 0 | AB26: 0 | AC26: 0 | AD26: 0 | AE26: 0.1 | AF26: 422 secondes
B27: FEUX DE STOP - Hdg / STOP lamp Hdg | I27: 0 | J27: 1 | K27: 1 | L27: 1 | M27: 0 | N27: 0 | O27: 0 | P27: 0 | R27: 1 | S27: 1 | T27: 0 | U27: 0 | V27: 0 | W27: 0 | Y27: 1 | Z27: 1 | AA27: 0 | AB27: 0 | AC27: 0 | AD27: 0 | AE27: 0.1 | AF27: 422 secondes
B28: FEUX DE CROISEMENT Edg / Low beam lamp | I28: 0 | J28: 1 | K28: 1 | L28: 1 | M28: 1 | N28: 1 | O28: 1 | P28: 1 | R28: 1 | S28: 1 | T28: 1 | U28: 1 | V28: 1 | W28: 1 | Y28: 1 | Z28: 1 | AA28: 1 | AB28: 1 | AC28: 1 | AD28: 1 | AE28: 1
B29: FEUX DE CROISEMENT Hdg / Low beam lamp | I29: 0 | J29: 1 | K29: 1 | L29: 1 | M29: 1 | N29: 1 | O29: 1 | P29: 1 | R29: 1 | S29: 1 | T29: 1 | U29: 1 | V29: 1 | W29: 1 | Y29: 1 | Z29: 1 | AA29: 1 | AB29: 1 | AC29: 1 | AD29: 1 | AE29: 1
B30: FEUX DE ROUTE Edg / High beam lamp | I30: 0 | J30: 0 | K30: 0 | L30: 0 | M30: 0 | N30: 0 | O30: 0 | P30: 0 | R30: 0 | S30: 0 | T30: 0 | U30: 0 | V30: 0 | W30: 0 | Y30: 0 | Z30: 0 | AA30: 0 | AB30: 0 | AC30: 0 | AD30: 0
B31: FEUX DE ROUTE Hdg / High beam lamp | I31: 0 | J31: 0 | K31: 0 | L31: 0 | M31: 0 | N31: 0 | O31: 0 | P31: 0 | R31: 0 | S31: 0 | T31: 0 | U31: 0 | V31: 0 | W31: 0 | Y31: 0 | Z31: 0 | AA31: 0 | AB31: 0 | AC31: 0 | AD31: 0
B32: VISIBILITE
B33: LUNETTE DEGIVRANTE / Rear Defroster | I33: 0 | J33: 1 | K33: 1 | L33: 0.95 | M33: 0.9 | N33: 0.9 | O33: 0 | P33: 0 | R33: 0 | S33: 0 | T33: 0 | U33: 0 | V33: 0 | W33: 0 | X33: 1 | Y33: 0 | Z33: 0 | AA33: 0 | AB33: 0 | AC33: 0 | AD33: 0 | AE33: 0 | AF33: 735s
B34: RETROVISEUR DEGIVRANT (x2) / Heated Mirror Defroster | I34: 0 | J34: 1 | K34: 1 | L34: 0.95 | M34: 0.9 | N34: 0.9 | O34: 0 | P34: 0 | R34: 0 | S34: 0 | T34: 0 | U34: 0 | V34: 0 | W34: 0 | X34: 1 | Y34: 0 | Z34: 0 | AA34: 0 | AB34: 0 | AC34: 0 | AD34: 0 | AE34: 0.8 | AF34: 735s
B35: PAREBRISE CHAUFFANT / Heated windscreen | I35: 0 | J35: 1 | K35: 1 | L35: 0 | M35: 0 | N35: 0 | O35: 0 | P35: 0 | R35: 0 | S35: 0 | T35: 0 | U35: 0 | V35: 0 | W35: 0 | X35: 1 | Y35: 0 | Z35: 0 | AA35: 0 | AB35: 0 | AC35: 0 | AD35: 0 | AE35: 0.15 | AF35: 4 min
B36: ESSUIE VITRE AVANT / FRONT WINDOW WIPER No activated if Heated windscreen is ON | I36: 0 | J36: 0 | K36: 0 | L36: 0 | M36: 0 | N36: 0 | O36: 0 | P36: 0 | R36: 0 | S36: 0 | T36: 0 | U36: 0 | V36: 0 | W36: 0 | Y36: 0 | Z36: 0 | AA36: 0 | AB36: 0 | AC36: 0 | AD36: 0
B37: ESSUIE VITRE ARRIERE / REAR WINDOW WIPER | I37: 0 | J37: 0 | K37: 0 | L37: 0 | M37: 0 | N37: 0 | O37: 0 | P37: 0 | R37: 0 | S37: 0 | T37: 0 | U37: 0 | V37: 0 | W37: 0 | Y37: 0 | Z37: 0 | AA37: 0 | AB37: 0 | AC37: 0 | AD37: 0
B38: CONFORT COCKPIT
B39: GMV (HVAC) HABITACLE _HOT MODE | I39: 0 | J39: 0 | K39: 0.9 | L39: 0.9 | M39: 0.7 | N39: 0.7 | O39: 0.2 | P39: 0.2 | R39: 0.2 | S39: 0.2 | T39: 0.2 | U39: 0.2 | V39: 0.2 | W39: 0.2 | Y39: 0.2 | Z39: 0.2 | AA39: 0.2 | AB39: 0.2 | AC39: 0.2 | AD39: 0.2 | AE39: 0
B40: GMV (HVAC) HABITACLE _COLD MODE | I40: 0 | J40: 1 | K40: 1 | L40: 1 | M40: 1 | N40: 1 | O40: 1 | P40: 1 | R40: 1 | S40: 1 | T40: 1 | U40: 1 | V40: 1 | W40: 1 | Y40: 1 | Z40: 1 | AA40: 1 | AB40: 1 | AC40: 1 | AD40: 1
B41: COMPRESSEUR CA HV | I41: 0 | J41: 0 | K41: 0 | L41: 0 | M41: 0 | N41: 0 | O41: 0 | P41: 0 | R41: 0 | S41: 0 | T41: 0 | U41: 0 | V41: 0 | W41: 0 | Y41: 0 | Z41: 0 | AA41: 0 | AB41: 0 | AC41: 0 | AD41: 0
B42: SIEGES CHAUFFANTS AVANTS | I42: 0 | J42: 0 | K42: 0 | L42: 0 | M42: 0 | N42: 0 | O42: 0 | P42: 0 | R42: 0 | S42: 0 | T42: 0 | U42: 0 | V42: 0 | W42: 0 | Y42: 0 | Z42: 0 | AA42: 0 | AB42: 0 | AC42: 0 | AD42: 0
B43: SIEGES CHAUFFANTS ARRIERES | I43: 0 | J43: 0 | K43: 0 | L43: 0 | M43: 0 | N43: 0 | O43: 0 | P43: 0 | R43: 0 | S43: 0 | T43: 0 | U43: 0 | V43: 0 | W43: 0 | Y43: 0 | Z43: 0 | AA43: 0 | AB43: 0 | AC43: 0 | AD43: 0
...

Sheet Graph -7°C
A9: ='Bilan -7°C'!E7 -> Cycle 1 | F9: ='Bilan -7°C'!F7 -> Cycle 2 | K9: ='Bilan -7°C'!G7 -> Cycle 3
A10: Time (Mint) | B10: Base Vehicle global conso (A) | C10: Upper Vehicle global conso (A) | D10: DCDC output | F10: Time (Mint) | G10: Base Vehicle global conso (A) | H10: Upper Vehicle global conso (A) | I10: DCDC output | K10: Time (Mint) | L10: Base Vehicle global conso (A) | M10: Upper Vehicle global conso (A) | N10: DCDC output
A11: 0 | B11: ='Bilan -7°C'!J95 -> 0 | C11: ='Bilan -7°C'!J94 -> 0 | D11: ='Bilan -7°C'!C92 -> 250 | F11: 0 | G11: ='Bilan -7°C'!R95 -> 0 | H11: ='Bilan -7°C'!R94 -> 0 | I11: ='Bilan -7°C'!$D$92 -> 250 | K11: 0 | L11: ='Bilan -7°C'!Y95 -> 0 | M11: ='Bilan -7°C'!Y94 -> 0 | N11: ='Bilan -7°C'!$D$92 -> 250
A12: 1.67 | B12: =B11 -> 0 | C12: =C11 -> 0 | D12: =D11 -> 250 | F12: 5 | G12: =G11 -> 0 | H12: =H11 -> 0 | I12: ='Bilan -7°C'!$D$92 -> 250 | K12: 5 | L12: =L11 -> 0 | M12: =M11 -> 0 | N12: ='Bilan -7°C'!$D$92 -> 250
A13: 1.67 | B13: ='Bilan -7°C'!K95 -> 0 | C13: ='Bilan -7°C'!K94 -> 0 | D13: =D11 -> 250 | F13: 5 | G13: ='Bilan -7°C'!S95 -> 0 | H13: ='Bilan -7°C'!S94 -> 0 | I13: ='Bilan -7°C'!$D$92 -> 250 | K13: 5 | L13: ='Bilan -7°C'!Z95 -> 0 | M13: ='Bilan -7°C'!Z94 -> 0 | N13: ='Bilan -7°C'!$D$92 -> 250
A14: 4 | B14: =B13 -> 0 | C14: =C13 -> 0 | D14: =D12 -> 250 | F14: 7 | G14: =G13 -> 0 | H14: =H13 -> 0 | I14: ='Bilan -7°C'!$D$92 -> 250 | K14: 7 | L14: =L13 -> 0 | M14: =M13 -> 0 | N14: ='Bilan -7°C'!$D$92 -> 250
A15: 4 | B15: ='Bilan -7°C'!L95 -> 0 | C15: ='Bilan -7°C'!L94 -> 0 | D15: =D11 -> 250 | F15: 7 | G15: ='Bilan -7°C'!T95 -> 0 | H15: ='Bilan -7°C'!T94 -> 0 | I15: ='Bilan -7°C'!$D$92 -> 250 | K15: 7 | L15: ='Bilan -7°C'!AA95 -> 0 | M15: ='Bilan -7°C'!AA94 -> 0 | N15: ='Bilan -7°C'!$D$92 -> 250
A16: 7 | B16: =B15 -> 0 | C16: =C15 -> 0 | D16: =D11 -> 250 | F16: 8.16 | G16: =G15 -> 0 | H16: =H15 -> 0 | I16: ='Bilan -7°C'!$D$92 -> 250 | K16: 8.16 | L16: =L15 -> 0 | M16: =M15 -> 0 | N16: ='Bilan -7°C'!$D$92 -> 250
A17: 7 | B17: ='Bilan -7°C'!M95 -> 0 | C17: ='Bilan -7°C'!M94 -> 0 | D17: =D11 -> 250 | F17: 8.16 | G17: ='Bilan -7°C'!U95 -> 0 | H17: ='Bilan -7°C'!U94 -> 0 | I17: ='Bilan -7°C'!$D$92 -> 250 | K17: 8.16 | L17: ='Bilan -7°C'!AB95 -> 0 | M17: ='Bilan -7°C'!AB94 -> 0 | N17: ='Bilan -7°C'!$D$92 -> 250
A18: 8.16 | B18: =B17 -> 0 | C18: =C17 -> 0 | D18: ='Bilan -7°C'!D92 -> 250 | F18: 15 | G18: =G17 -> 0 | H18: =H17 -> 0 | I18: ='Bilan -7°C'!$D$92 -> 250 | K18: 15 | L18: =L17 -> 0 | M18: =M17 -> 0 | N18: ='Bilan -7°C'!$D$92 -> 250
A19: 8.16 | B19: ='Bilan -7°C'!N95 -> 0 | C19: ='Bilan -7°C'!N94 -> 0 | D19: ='Bilan -7°C'!D92 -> 250 | F19: 15 | G19: ='Bilan -7°C'!V95 -> 0 | H19: ='Bilan -7°C'!V94 -> 0 | I19: ='Bilan -7°C'!$D$92 -> 250 | K19: 15 | L19: ='Bilan -7°C'!AC95 -> 0 | M19: ='Bilan -7°C'!AC94 -> 0 | N19: ='Bilan -7°C'!$D$92 -> 250
A20: 12.25 | B20: =B19 -> 0 | C20: =C19 -> 0 | D20: ='Bilan -7°C'!D92 -> 250 | F20: 25 | G20: =G19 -> 0 | H20: =H19 -> 0 | I20: ='Bilan -7°C'!$D$92 -> 250 | K20: 25 | L20: =L19 -> 0 | M20: =M19 -> 0 | N20: ='Bilan -7°C'!$D$92 -> 250
A21: 12.25 | B21: ='Bilan -7°C'!O95 -> 0 | C21: ='Bilan -7°C'!O94 -> 0 | D21: ='Bilan -7°C'!D92 -> 250 | F21: 25 | G21: ='Bilan -7°C'!W95 -> 0 | H21: ='Bilan -7°C'!W94 -> 0 | I21: ='Bilan -7°C'!$D$92 -> 250 | K21: 25 | L21: ='Bilan -7°C'!AD95 -> 0 | M21: ='Bilan -7°C'!AD94 -> 0 | N21: ='Bilan -7°C'!$D$92 -> 250
A22: 25 | B22: =B21 -> 0 | C22: =C21 -> 0 | D22: ='Bilan -7°C'!D92 -> 250 | F22: 30 | G22: =G21 -> 0 | H22: =H21 -> 0 | I22: ='Bilan -7°C'!$D$92 -> 250 | K22: 30 | L22: =L21 -> 0 | M22: =M21 -> 0 | N22: ='Bilan -7°C'!$D$92 -> 250
A23: 25 | B23: ='Bilan -7°C'!P95 -> 0 | C23: ='Bilan -7°C'!P94 -> 0 | D23: ='Bilan -7°C'!D92 -> 250
A24: 30 | B24: =B23 -> 0 | C24: =C23 -> 0 | D24: ='Bilan -7°C'!D92 -> 250
